Workbook

Sheet imagens
A1: pasta | B1: volume | C1: imagem | D1: url_pagina | E1: imagens_texto | F1: Categoria-1 | G1: Categoria-2 | H1: Categoria-3 | I1: ncb | J1: purl | K1: capa | L1: tipo de material | M1: língua | N1: língua da obra original | O1: título | P1: subtítulo | Q1: título original | R1: edição | S1: publicação | T1: data da publicação | U1: data da publicação2 | V1: dimensões | W1: autor | X1: autor - organização | Y1: co-autores | Z1: autores secundários | AA1: co-autores - organizações | AB1: autores secundários - organizações | AC1: cota | AD1: coleção | AE1: id persistente | AF1: acesso
A2: 367428 | B2: 1 | C2: 1 | D2: https://permalinkbnd.bnportugal.gov.pt/viewer/272369/?offset=#page=1&viewer=picture&o=info&n=0&q= | E2: 1 | I2: 367428 | J2: https://purl.pt/43428 | K2: https://bndigital.bnportugal.gov.pt//i/?IIIF=/a3/eb/b0/67/a3ebb067-89f3-40ff-a518-1fc158846d4b/iiif/cam-479-p_0003.tif/full/!300,500/0/default.jpg | L2: Livro impresso | M2: Italiano | O2: I Lusiadi | P2: poema | R2: 1.ª ed. | S2: Milano : Edoardo Sonzogno,editore | T2: 1882 | U2: 1882 | V2: 196 p. | W2: Camões, Luís de, 1524-1580 | Z2: Nervi, Antonio, 1760-1836, Tradutor | AC2: CAM. 479 P. | AD2: CAM500 | AE2: http://id.bnportugal.gov.pt/bib/catbnp/367428 | AF2: Livre
A3: 381074 | B3: 1 | C3: 499 | D3: https://permalinkbnd.bnportugal.gov.pt/viewer/274089/?offset=#page=499&viewer=picture&o=info&n=0&q= | E3: 10 [site], 11, 103 [site pelicano direita], 107, 142, 107, 142, 145, 185, 235, 270 [site assassinato de Inês], 273, 306, 309 [site ninfas], 342, 345, 374, 377, 410, 413, 447, 499, 526 [site apontamento] [pintura de Camões por Columbano, portada, fac-símile do frontispício da 1.ª Ed. de Os Lusíadas, ilustrações da obra] | F3: Cantos - Canto I|1791 | G3: Episódios - Concílio "Conselho dos Deuses"|1809 | H3: Retratos - |1801 | I3: 381074 | J3: https://purl.pt/43747 | K3: https://bndigital.bnportugal.gov.pt//i/?IIIF=/7d/bb/9c/38/7dbb9c38-ff88-4f0e-8125-42d713ee62f7/iiif/cam-21-a_0007.tif/full/!300,500/0/default.jpg | L3: Livro impresso | M3: Português | O3: Os Lusíadas | P3: edição consagrada a comemorar o terceiro centenário do poeta... | R3: 1.ª ed. | S3: Lisboa : Of. de Castro Irmão | T3: 1880 | U3: 1880 | V3: XCIII, 422 p., 1 il. | W3: Camões, Luís de, 1524-1580 | Z3: Coelho, Adolfo, 1847-1919, Revisor ; Ortigão, Ramalho, 1836-1915, Autor da introdução, etc. ; Montoro, Reinaldo Carlos, 1831-?, Autor da introdução, etc. | AB3: Gabinete Português de Leitura, Editor literário | AC3: L. 94571 V. | AD3: CAM500 | AE3: http://id.bnportugal.gov.pt/bib/catbnp/381074 | AF3: Livre
A4: 381465 | B4: 1 | C4: 644 | D4: https://permalinkbnd.bnportugal.gov.pt/viewer/271573/?offset=#page=644&viewer=picture&o=info&n=0&q= | E4: 5 [site], 10 [site], 11 [site], 43, 46 [Vasco da Gama], 47, 100, 101, 160, 161, 163, 235, 237, 289, 291 [site Adamastor], 293, 343 [site apontamento livros e pena], 345, 347, 397, 443, 445, 495 [site Mercúrio, caduceu e navegador], 545 [site máquina do mundo], 547, 625, 627, 644 [monge com livro] [portadas, retrato de Camões, fotogravuras em cada Canto] | F4: Cantos - Canto II|1792 | G4: Episódios - Vénus aplaca os Ventos e a tormenta|1813 | H4: Retratos - Vasco da Gama|1803 | I4: 381465 | J4: https://purl.pt/43233 | K4: https://bndigital.bnportugal.gov.pt//i/?IIIF=/1b/9b/a2/7b/1b9ba27b-8449-49d7-b8fa-ec3081a88a08/iiif/cam-30-a_0000_000005.tif/full/!300,500/0/default.jpg | L4: Livro impresso | M4: Português | O4: Os Lusíadas | P4: profusamente illustrada com desenhos allegoricos... | R4: 1.ª ed. | S4: Lisboa : Silvestre Castanheiro | T4: 1898 | U4: 1898 | V4: XXXIII, 599 p. | W4: Camões, Luís de, 1524-1580 | Z4: Belo, António Mendes, 1842-1929, Comentador (em meio audiovisual) ; Chagas, Pinheiro, 1842-1895, Comentador (em meio audiovisual) ; Costa, José Fernandes, 1848-1920, Comentador (em meio audiovisual) | AC4: L. 5864 A. | AD4: CAM500 | AE4: http://id.bnportugal.gov.pt/bib/catbnp/381465 | AF4: Livre
A5: 381468 | B5: 1 | C5: 8 | D5: https://permalinkbnd.bnportugal.gov.pt/viewer/274087/?offset=#page=8&viewer=picture&o=info&n=0&q= | E5: 8 [site retrato de Camões] | F5: Cantos - Canto III|1793 | G5: Episódios - Sonho d'El-Rei D. Manuel, no qual lhe aparecem os rios Indo e Ganges|1810 | H5: Retratos - António José Gomes Monteiro|1805 | I5: 381468 | J5: https://purl.pt/43745 | K5: https://bndigital.bnportugal.gov.pt//i/?IIIF=/e0/20/89/c0/e02089c0-dfb3-4507-bf34-b897aa5b2b44/iiif/cam-33-a_0009.tif/full/!300,500/0/default.jpg | L5: Livro impresso | M5: Espanhol | N5: Português | O5: Os Lusiadas (Los Portugueses) | R5: Edicion acompañada del legitimo texto portugues y de copiosas notas y noticias biograficas sobre el insigne poeta ibero | S5: Badajoz : Establecimiento Tipográfico de José Santamaría | T5: 1873 | U5: 1873 | V5: 263, 1 p. | W5: Camões, Luís de, 1524-1580 | Z5: Soler y Arqués, Carlos, 1836-1896, Tradutor | AC5: CAM. 33 A. | AD5: CAM500 | AE5: http://id.bnportugal.gov.pt/bib/catbnp/381468 | AF5: Livre
A6: 381701 | B6: 1 | C6: 11 | D6: https://permalinkbnd.bnportugal.gov.pt/viewer/281141/?offset=#page=11&viewer=picture&o=info&n=0&q= | E6: 11 | F6: Cantos - Canto VI|1796 | G6: Retratos - Vasco da Gama|1803 | H6: Episódios - Concílio "Conselho dos Deuses"|1809 | I6: 381701 | J6: https://purl.pt/43724 | K6: https://bndigital.bnportugal.gov.pt//i/?IIIF=/58/a8/a6/57/58a8a657-7fb2-4700-9b55-408036c37806/iiif/cam-40-a_0001.tif/full/!300,500/0/default.jpg | L6: Livro impresso | M6: Poliglota | N6: Português | O6: Inês de Castro | P6: episódio extraído do canto terceiro do poema épico Os Lusíadas | R6: 1.ª ed. | S6: Lisboa : Imprensa Nacional | T6: 1873 | U6: 1873 | V6: 76 p. | W6: Camões, Luís de, 1524-1580 | AC6: CAM. 40 A. | AD6: CAM500 | AE6: http://id.bnportugal.gov.pt/bib/catbnp/381701 | AF6: Livre
A7: 381889 | B7: 1 | C7: 1 | D7: https://permalinkbnd.bnportugal.gov.pt/viewer/273118/?offset=#page=1&viewer=picture&o=info&n=0&q= | E7: 1 [Inês de Castro, Vasco da Gama, Catarina de Ataíde e retrato de Camões] | F7: Cantos - Canto VI|1796 | I7: 381889 | J7: https://purl.pt/43659 | K7: https://bndigital.bnportugal.gov.pt//i/?IIIF=/5b/91/40/8a/5b91408a-4af1-4a94-bccc-2d03ee894a1c/iiif/cam-44-2-a_0000_000001.tif/full/!300,500/0/default.jpg | L7: Periódico | M7: Português | O7: Pérolas de Camões | P7: publicação dedicada ao povo | R7: 1.ª ed. | S7: Lisboa : Lallement Fréres | T7: 1880 | U7: 1880 | AB7: Lallement Frères, Editor comercial | AC7: CAM. 44//2 A. | AD7: CAM500 | AE7: http://id.bnportugal.gov.pt/bib/catbnp/381889 | AF7: Livre
A8: 381903 | B8: 1 | C8: 5 | D8: https://permalinkbnd.bnportugal.gov.pt/viewer/270037/?offset=#page=5&viewer=picture&o=info&n=0&q= | E8: 5 [1.º] | F8: Cantos - Canto V|1795 | G8: Retratos - Camões|1802 | I8: 381903 | J8: https://purl.pt/42920 | K8: https://bndigital.bnportugal.gov.pt//i/?IIIF=/84/00/0c/50/84000c50-b90e-4a7c-aa5e-5cb3dfef4dab/iiif/cam-45-2-a_0000_000001.tif/full/!300,500/0/default.jpg | L8: Periódico | M8: Polaco | O8: Illustrowane Tygedniowe | R8: 1.ª ed. | T8: 1880 | U8: 1880 | AC8: CAM. 45//2 A. | AD8: CAM500 | AE8: http://id.bnportugal.gov.pt/bib/catbnp/381903 | AF8: Livre
A9: 382749 | B9: 1 | C9: 7 | D9: https://permalinkbnd.bnportugal.gov.pt/viewer/270109/?offset=#page=7&viewer=picture&o=info&n=0&q= | E9: 7 [site], 19, 23 [frisos site, esta obra contém mais apontamentos e frisos belíssimos] | F9: Episódios - Vénus aplaca os Ventos e a tormenta|1813 | I9: 382749 | J9: https://purl.pt/42835 | K9: https://bndigital.bnportugal.gov.pt//i/?IIIF=/60/58/22/4f/6058224f-9454-448f-8489-96a3a71253f5/iiif/cam-47-a_0000_000007.tif/full/!300,500/0/default.jpg | L9: Livro impresso | M9: Português | O9: Pretidão de amor | P9: endechas a Bárbara escrava seguidas da respectiva tradução em várias línguas... | R9: 1.ª ed. | S9: Lisboa : Imprensa Nacional | T9: 1893 | U9: 1893 | V9: 2 v. | W9: Camões, Luís de, 1524-1580 | Z9: Cunha, Xavier da, 1840-1920, Autor da introdução, etc. | AC9: CAM. 270 V. | AD9: CAM500 | AE9: http://id.bnportugal.gov.pt/bib/catbnp/382749 | AF9: Livre
A10: 382749 | B10: 1 | C10: 19 | D10: https://permalinkbnd.bnportugal.gov.pt/viewer/270109/?offset=#page=19&viewer=picture&o=info&n=0&q= | F10: Retratos - Vasco da Gama|1803 | I10: 382749 | J10: https://purl.pt/42835 | K10: https://bndigital.bnportugal.gov.pt//i/?IIIF=/60/58/22/4f/6058224f-9454-448f-8489-96a3a71253f5/iiif/cam-47-a_0000_000007.tif/full/!300,500/0/default.jpg | L10: Livro impresso | M10: Português | O10: Pretidão de amor | P10: endechas a Bárbara escrava seguidas da respectiva tradução em várias línguas... | R10: 1.ª ed. | S10: Lisboa : Imprensa Nacional | T10: 1893 | U10: 1893 | V10: 2 v. | W10: Camões, Luís de, 1524-1580 | Z10: Cunha, Xavier da, 1840-1920, Autor da introdução, etc. | AC10: CAM. 270 V. | AD10: CAM500 | AE10: http://id.bnportugal.gov.pt/bib/catbnp/382749 | AF10: Livre
A11: 382749 | B11: 1 | C11: 23 | D11: https://permalinkbnd.bnportugal.gov.pt/viewer/270109/?offset=#page=23&viewer=picture&o=info&n=0&q= | I11: 382749 | J11: https://purl.pt/42835 | K11: https://bndigital.bnportugal.gov.pt//i/?IIIF=/60/58/22/4f/6058224f-9454-448f-8489-96a3a71253f5/iiif/cam-47-a_0000_000007.tif/full/!300,500/0/default.jpg | L11: Livro impresso | M11: Português | O11: Pretidão de amor | P11: endechas a Bárbara escrava seguidas da respectiva tradução em várias línguas... | R11: 1.ª ed. | S11: Lisboa : Imprensa Nacional | T11: 1893 | U11: 1893 | V11: 2 v. | W11: Camões, Luís de, 1524-1580 | Z11: Cunha, Xavier da, 1840-1920, Autor da introdução, etc. | AC11: CAM. 270 V. | AD11: CAM500 | AE11: http://id.bnportugal.gov.pt/bib/catbnp/382749 | AF11: Livre
A12: 382834 | B12: 1 | C12: 11 | D12: https://permalinkbnd.bnportugal.gov.pt/viewer/273316/?offset=#page=11&viewer=picture&o=info&n=0&q= | E12: 11 [caravela com Vasco da Gama] | I12: 382834 | J12: https://purl.pt/43815 | K12: https://bndigital.bnportugal.gov.pt//i/?IIIF=/b6/d0/71/c6/b6d071c6-e05d-4c17-96b2-07a62e35fb7f/iiif/cam-82-1-v_0000_000005.tif/full/!300,500/0/default.jpg | L12: Livro impresso | M12: Português | O12: Comemoração gloriosa da morte de Luiz de Camões 10 de Junho de 1889 | R12: 1.ª ed. | S12: Evora : Minerva Eborense de J. José Baptista, Rua d'Aviz | T12: 1889 | U12: 1889 | V12: 12, 4 p. | W12: Barata, António Francisco, 1836-1910 | Z12: Camões, Luís de, 1524-1580, Antecedente bibliográfico | AC12: CAM. 309//13 V. | AD12: CAM500 | AE12: http://id.bnportugal.gov.pt/bib/catbnp/382834 | AF12: Livre
A13: 382844 | B13: 1 | C13: 3 | D13: https://permalinkbnd.bnportugal.gov.pt/viewer/271559/?offset=#page=3&viewer=picture&o=info&n=0&q= | E13: 3 | I13: 382844 | J13: https://purl.pt/43227 | K13: https://bndigital.bnportugal.gov.pt//i/?IIIF=/be/12/df/5e/be12df5e-248d-4e0b-823f-bb93ea5db616/iiif/cam-2058-v_0001.tif/full/!300,500/0/default.jpg | L13: Livro impresso | M13: Português | O13: A Luiz de Camões | P13: com notas curiosas e tres ineditos do poeta | R13: 1.ª ed. | S13: Evora : Tip. Minerva, de A.F. Barata | T13: 1880 | U13: 1880 | V13: 24 p. | W13: Barata, António Francisco, 1836-1910 | Z13: Camões, Luís de, 1524-1580, Antecedente bibliográfico | AC13: L. 599//32 A. | AD13: CAM500 | AE13: http://id.bnportugal.gov.pt/bib/catbnp/382844 | AF13: Livre
A14: 382955 | B14: 1 | C14: 6 | D14: https://permalinkbnd.bnportugal.gov.pt/viewer/274171/?offset=#page=6&viewer=picture&o=info&n=0&q= | E14: 6 [site, retrato do Poeta laureado] | I14: 382955 | J14: https://purl.pt/43816 | K14: https://bndigital.bnportugal.gov.pt//i/?IIIF=/df/8e/1b/e5/df8e1be5-0f74-4fdb-9b58-5bfa696ca99d/iiif/cam-53-5-a_0001.tif/full/!300,500/0/default.jpg | L14: Livro impresso | M14: Português | O14: Auto da cunhagem da medalha comemorativa das festas da Grande Comissão Portuense... | R14: 1.ª ed. | S14: Porto : s. n. | T14: 1880 | U14: 1880 | X14: Grande Comissão Portuense | Z14: Camões, Luís de, 1524-1580, Antecedente bibliográfico | AC14: CAM. 53//5 A. | AD14: CAM500 | AE14: http://id.bnportugal.gov.pt/bib/catbnp/382955 | AF14: Livre
A15: 382972 | B15: 1 | C15: 14 | D15: https://permalinkbnd.bnportugal.gov.pt/viewer/274229/?offset=#page=14&viewer=picture&o=info&n=0&q= | E15: 14 [site, imagem da medalha/gravura comemorativa do monumento erigido à memória do Poeta] | I15: 382972 | J15: https://purl.pt/43819 | K15: https://bndigital.bnportugal.gov.pt//i/?IIIF=/80/3b/b9/df/803bb9df-b4de-496a-adbc-25a9d95b3638/iiif/cam-55-a_0007.tif/full/!300,500/0/default.jpg | L15: Livro impresso | M15: Português | O15: Surrexit | P15: homenagem a Luís de Camões | R15: 1.ª ed. | S15: Lisboa : Imprensa Nacional | T15: 1880 | U15: 1880 | W15: Ribeiro, Tomás, 1831-1901 | AC15: CAM. 55 A. | AD15: CAM500 | AE15: http://id.bnportugal.gov.pt/bib/catbnp/382972 | AF15: Livre
A16: 382978 | B16: 1 | C16: 7 | D16: https://permalinkbnd.bnportugal.gov.pt/viewer/274235/?offset=#page=7&viewer=picture&o=info&n=0&q= | E16: 7 [site], 13 [site, itinerário do cortejo triunfal], 15 [site préstito cívico e triunfal] | I16: 382978 | J16: https://purl.pt/43823 | K16: https://bndigital.bnportugal.gov.pt//i/?IIIF=/8a/04/06/d1/8a0406d1-dcdf-40af-9ba2-5fa354405f51/iiif/cam-56-a_0001.tif/full/!300,500/0/default.jpg | L16: Livro impresso | M16: Português | O16: Programa da celebração em Lisboa do terceiro centenário de Luís de Camões | P16: comemoração promovida pela imprensa jornalística auxiliada pela Câmara Municipal | R16: 1.ª ed. | S16: Lisboa : Tip. Universal | T16: 1880 | U16: 1880 | V16: 8 p. | Z16: Camões, Luís de, 1524-1580, Antecedente bibliográfico | AC16: CAM. 134 A. | AD16: CAM500 | AE16: http://id.bnportugal.gov.pt/bib/catbnp/382978 | AF16: Livre
A17: 382978 | B17: 1 | C17: 13 | D17: https://permalinkbnd.bnportugal.gov.pt/viewer/274235/?offset=#page=13&viewer=picture&o=info&n=0&q= | E17: 7 [site], 13 [site, itinerário do cortejo triunfal], 15 [site préstito cívico e triunfal] | I17: 382978 | J17: https://purl.pt/43823 | K17: https://bndigital.bnportugal.gov.pt//i/?IIIF=/8a/04/06/d1/8a0406d1-dcdf-40af-9ba2-5fa354405f51/iiif/cam-56-a_0001.tif/full/!300,500/0/default.jpg | L17: Livro impresso | M17: Português | O17: Programa da celebração em Lisboa do terceiro centenário de Luís de Camões | P17: comemoração promovida pela imprensa jornalística auxiliada pela Câmara Municipal | R17: 1.ª ed. | S17: Lisboa : Tip. Universal | T17: 1880 | U17: 1880 | V17: 8 p. | Z17: Camões, Luís de, 1524-1580, Antecedente bibliográfico | AC17: CAM. 134 A. | AD17: CAM500 | AE17: http://id.bnportugal.gov.pt/bib/catbnp/382978 | AF17: Livre
A18: 382978 | B18: 1 | C18: 15 | D18: https://permalinkbnd.bnportugal.gov.pt/viewer/274235/?offset=#page=15&viewer=picture&o=info&n=0&q= | E18: 7 [site], 13 [site, itinerário do cortejo triunfal], 15 [site préstito cívico e triunfal] | I18: 382978 | J18: https://purl.pt/43823 | K18: https://bndigital.bnportugal.gov.pt//i/?IIIF=/8a/04/06/d1/8a0406d1-dcdf-40af-9ba2-5fa354405f51/iiif/cam-56-a_0001.tif/full/!300,500/0/default.jpg | L18: Livro impresso | M18: Português | O18: Programa da celebração em Lisboa do terceiro centenário de Luís de Camões | P18: comemoração promovida pela imprensa jornalística auxiliada pela Câmara Municipal | R18: 1.ª ed. | S18: Lisboa : Tip. Universal | T18: 1880 | U18: 1880 | V18: 8 p. | Z18: Camões, Luís de, 1524-1580, Antecedente bibliográfico | AC18: CAM. 134 A. | AD18: CAM500 | AE18: http://id.bnportugal.gov.pt/bib/catbnp/382978 | AF18: Livre
A19: 382981 | B19: 1 | C19: 9 | D19: https://permalinkbnd.bnportugal.gov.pt/viewer/1880/?offset=#page=9&viewer=picture&o=info&n=0&q= | E19: 9 | I19: 382981 | J19: https://purl.pt/43818 | K19: https://bndigital.bnportugal.gov.pt//i/?IIIF=/2b/2d/51/1b/2b2d511b-4290-4cc3-b338-dffc6cbedad2/iiif/cam-57-a_0001.tif/full/!300,500/0/default.jpg | L19: Livro impresso | M19: Português | O19: Relatório da Directoria do Gabinete de Leitura do Rio de Janeiro em 1880 | R19: 1.ª ed. | S19: Rio de Janeiro : Tip e lit. Moreira Maximino | T19: 1881 | U19: 1881 | AB19: Real Gabinete Português de Leitura do Rio de Janeiro | AC19: CAM. 57 A. | AD19: CAM500 | AE19: http://id.bnportugal.gov.pt/bib/catbnp/382981 | AF19: Livre
A20: 385945 | B20: 1 | C20: 15 | D20: https://permalinkbnd.bnportugal.gov.pt/viewer/273149/?offset=#page=15&viewer=picture&o=info&n=0&q= | E20: 10 [fotografia do autor], 11 [portada], 15 | I20: 385945 | J20: https://purl.pt/43873 | K20: https://bndigital.bnportugal.gov.pt//i/?IIIF=/ca/5d/8c/c5/ca5d8cc5-b85c-4f76-893f-7de2d31a6d43/iiif/cam-63-a_0000_000007.tif/full/!300,500/0/default.jpg | L20: Livro impresso | M20: Poliglota | N20: Português | O20: Álbum literário comemorativo do terceiro centenário de Luís de Camões | R20: 1.ª ed. | S20: Porto : Tip. Ocidental | T20: 1880 | U20: 1880 | V20: 28 p. | Z20: Esteves, Francisco Xavier, 1864-1944, Editor literário | AC20: CAM. 133 A. | AD20: CAM500 | AE20: http://id.bnportugal.gov.pt/bib/catbnp/385945 | AF20: Livre
A21: 385949 | B21: 1 | C21: 1 | D21: https://permalinkbnd.bnportugal.gov.pt/viewer/274256/?offset=#page=1&viewer=picture&o=info&n=0&q= | E21: 1 | I21: 385949 | J21: https://purl.pt/43866 | K21: https://bndigital.bnportugal.gov.pt//i/?IIIF=/06/33/d8/97/0633d897-92cc-4a30-beb0-aa004a6f6470/iiif/cam-64-1-a_0001.tif/full/!300,500/0/default.jpg | L21: Livro impresso | M21: Português | O21: Homenagem a Camões | P21: Luís de Camões e a nacionalidade portuguesa | R21: 1.ª ed. | S21: São Miguel : s. n. | T21: 1880 | U21: 1880 | X21: Centro Republicano Federal de Ponta Delgada | AC21: CAM. 64//1 A. | AD21: CAM500 | AE21: http://id.bnportugal.gov.pt/bib/catbnp/385949 | AF21: Livre
A22: 386935 | B22: 1 | C22: 1 | D22: https://permalinkbnd.bnportugal.gov.pt/viewer/273122/?offset=#page=1&viewer=picture&o=info&n=0&q= | E22: 1 | I22: 386935 | J22: https://purl.pt/43871 | K22: https://bndigital.bnportugal.gov.pt//i/?IIIF=/c8/18/91/78/c8189178-5871-4300-9edd-154703c6e75a/iiif/cam-64-3-a_0000_000001.tif/full/!300,500/0/default.jpg | L22: Livro impresso | M22: Português | O22: Vianna a Camões | P22: comemoração do tricentenário do imortal cantor dos Lusíadas | R22: 1.ª ed. | S22: Viana do Castelo : André Jorge Pereira & Filho | T22: 1880 | U22: 1880 | AC22: CAM. 64//3 A. | AD22: CAM500 | AE22: http://id.bnportugal.gov.pt/bib/catbnp/386935 | AF22: Livre
A23: 386992 | B23: 1 | C23: 1 | D23: https://permalinkbnd.bnportugal.gov.pt/viewer/273124/?offset=#page=1&viewer=picture&o=info&n=0&q= | E23: 1 | I23: 386992 | J23: https://purl.pt/43661 | K23: https://bndigital.bnportugal.gov.pt//i/?IIIF=/0c/53/05/58/0c530558-6907-414a-974d-e379f3070104/iiif/cam-64-4-a_0000_000001.tif/full/!300,500/0/default.jpg | L23: Livro impresso | M23: Português | O23: Homenagem da Sociedade Amizade, Recreio e Ínstrução | R23: 1.ª ed. | S23: S. Miguel : Lit. dos Açores | T23: 1880 | U23: 1880 | Z23: Camões, Luís de, 1524-1580, Antecedente bibliográfico | AB23: Sociedade Amizade Recreio e Ínstrução | AC23: CAM. 64//4 A. | AD23: CAM500 | AE23: http://id.bnportugal.gov.pt/bib/catbnp/386992 | AF23: Livre
A24: 396405 | B24: 1 | C24: 1 | D24: https://permalinkbnd.bnportugal.gov.pt/viewer/36059/?offset=#page=1&viewer=picture&o=info&n=0&q= | E24: 1 | I24: 396405 | J24: https://purl.pt/6115 | K24: https://bndigital.bnportugal.gov.pt//i/?IIIF=/11/21/33/35/11213335-0c6f-4347-8501-397d47049e54/iiif/e-2172-v_0000_1-2_p24-C-R0150_000001.tif/full/!300,500/0/default.jpg | L24: Iconografia | M24: Português | O24: Luís de Camões | R24: 1.ª ed. | S24: Macau : Com. Org. Comem. Dia de Portugal de Camões e das Comunid. Portuguesas | T24: 1992 | U24: 1992 | V24: 1 imagem | W24: Fialho, Fernando Jorge, 1965- | AC24: PURL 6115/0 | AE24: http://id.bnportugal.gov.pt/bib/catbnp/396405 | AF24: Interno
A25: 397670 | B25: 1 | C25: 11 | D25: https://permalinkbnd.bnportugal.gov.pt/viewer/273150/?offset=#page=11&viewer=picture&o=info&n=0&q= | E25: 11, 13 [apontamento sobre o Centenário de Camões, site?] | I25: 397670 | J25: https://purl.pt/43874 | K25: https://bndigital.bnportugal.gov.pt//i/?IIIF=/f4/b1/c2/b3/f4b1c2b3-f0bb-4cb4-b767-93d0dae46bc3/iiif/cam-70-v_0000_000007.tif/full/!300,500/0/default.jpg | L25: Livro impresso | M25: Português ; Francês | O25: Episodio da Ilha de Venus extrahido dos Lusiadas de Camões | R25: 1.ª ed. | S25: Braga : Typ. Lealdade : Sociedade Democrática Recreativa | T25: 1880 | U25: 1880 | V25: 23 p. | W25: Camões, Luís de, 1524-1580 | Z25: Caldas, José Joaquim da Silva Pereira, 1818-1903, Autor da introdução, etc. ; Cournand, Antoine de, Autor da introdução, etc. | AC25: L. 5895//9 A | AD25: CAM500 | AE25: http://id.bnportugal.gov.pt/bib/catbnp/397670 | AF25: Livre
A26: 397818 | B26: 1 | C26: 6 | D26: https://permalinkbnd.bnportugal.gov.pt/viewer/272368/?offset=#page=6&viewer=picture&o=info&n=0&q= | E26: 6, 106 [retrato de Camões, padrão levantado por Vasco da Gama] | I26: 397818 | J26: https://purl.pt/43426 | K26: https://bndigital.bnportugal.gov.pt//i/?IIIF=/58/13/66/39/58136639-f7f1-4612-94b8-d6a78a970d34/iiif/cam-707-p_0007.tif/full/!300,500/0/default.jpg | L26: Livro impresso | M26: Português | O26: Os Lusíadas | P26: poema épico | R26: Nova ed., cuidadosamente revista | S26: Lisboa : Livraria de António Maria Pereira | T26: 1891 | U26: 1891 | V26: XVIII, 457 p., 2 est. | W26: Camões, Luís de, 1524-1580 | Z26: Silva, Inocêncio Francisco da, 1810-1876, Autor da introdução, etc. | AC26: CAM. 707 P. | AD26: CAM500 | AE26: http://id.bnportugal.gov.pt/bib/catbnp/397818 | AF26: Livre
A27: 397822 | B27: 1 | C27: 7 | D27: https://permalinkbnd.bnportugal.gov.pt/viewer/274090/?offset=#page=7&viewer=picture&o=info&n=0&q= | E27: 7, 388 [apontamento site] | I27: 397822 | J27: https://purl.pt/43741 | K27: https://bndigital.bnportugal.gov.pt//i/?IIIF=/53/07/f6/e6/5307f6e6-7747-45f0-8d9c-435d2871d068/iiif/cam-35-v_0007.tif/full/!300,500/0/default.jpg | L27: Livro impresso | M27: Português | O27: Os Lusíadas | R27: Ed. comemorativa do IV Centenário do Descobrimento Marítimo da India | S27: Lisboa : Typographia do Commercio | T27: 1898 | U27: 1898 | V27: 186 fls. | W27: Camões, Luís de, 1524-1580 | AC27: CAM. 35 V. | AD27: CAM500 | AE27: http://id.bnportugal.gov.pt/bib/catbnp/397822 | AF27: Livre
A28: 397852 | B28: 1 | C28: 14 | D28: https://permalinkbnd.bnportugal.gov.pt/viewer/274172/?offset=#page=14&viewer=picture&o=info&n=0&q= | E28: 14 [vinheta site] | I28: 397852 | J28: https://purl.pt/43811 | K28: https://bndigital.bnportugal.gov.pt//i/?IIIF=/97/d2/74/d0/97d274d0-35d0-4540-bdbb-0b1af3d4ba91/iiif/cam-45-v_0005.tif/full/!300,500/0/default.jpg | L28: Livro impresso | M28: Francês ; Português | O28: Les Lusiades | P28: chant primier | R28: Edition commemorative du septieme anniversaire du tricentenaire de Camöes | S28: Lisboa : Imprensa Nacional | T28: 1887 | U28: 1887 | V28: 79 p. | W28: Camões, Luís de, 1524-1580 | Z28: Courtois, Henri de, Tradutor | AC28: L. 5907//7 A. | AD28: CAM500 | AE28: http://id.bnportugal.gov.pt/bib/catbnp/397852 | AF28: Livre
A29: 397863 | B29: 1 | C29: 11 | D29: https://permalinkbnd.bnportugal.gov.pt/viewer/273148/?offset=#page=11&viewer=picture&o=info&n=0&q= | E29: 11 [portada] | I29: 397863 | J29: https://purl.pt/43931 | K29: https://bndigital.bnportugal.gov.pt//i/?IIIF=/c3/91/eb/4c/c391eb4c-8bd2-4992-a05f-625f8ef77ebc/iiif/cam-69-v_0000_000001.tif/full/!300,500/0/default.jpg | L29: Livro impresso | M29: Português | O29: A Ode de Luiz de Camões ao Conde do Redondo, restituida á sua primitiva licção | R29: Edição commemorativa do 4º anniversario do Tricentenario Camoniano | S29: Lisboa : Typographia Elzeviriana | T29: 1884 | U29: 1884 | V29: 22, 2 p. | W29: Camões, Luís de, 1524-1580 | Z29: Cunha, Xavier da, 1840-1920, Editor literário ; Carvalho, Alfredo de, fl. 1884, Tipógrafo | AC29: CAM. 69 V. | AD29: CAM500 | AE29: http://id.bnportugal.gov.pt/bib/catbnp/397863 | AF29: Livre
A30: 397876 | B30: 1 | C30: 9 | D30: https://permalinkbnd.bnportugal.gov.pt/viewer/274230/?offset=#page=9&viewer=picture&o=info&n=0&q= | E30: 9 | I30: 397876 | J30: https://purl.pt/43825 | K30: https://bndigital.bnportugal.gov.pt//i/?IIIF=/de/b5/45/9c/deb5459c-316c-4583-bb29-fa7038aaebdc/iiif/cam-59-v_0009.tif/full/!300,500/0/default.jpg | L30: Livro impresso | M30: Francês | N30: Português | O30: Sonnets choisis | R30: 1.ª ed. | S30: Paris : Plon | T30: 1879 | U30: 1879 | V30: VII, 40 p. | W30: Camões, Luís de, 1524-1580 | Z30: Cazaubon, Léonce, Tradutor | AC30: CAM. 59 V. | AD30: CAM500 | AE30: http://id.bnportugal.gov.pt/bib/catbnp/397876 | AF30: Livre
A31: 397877 | B31: 1 | C31: 9 | D31: https://permalinkbnd.bnportugal.gov.pt/viewer/1576/?offset=#page=9&viewer=picture&o=info&n=0&q= | E31: 9 [retrato de Camões] | I31: 397877 | J31: https://purl.pt/43875 | K31: https://bndigital.bnportugal.gov.pt//i/?IIIF=/3a/34/50/28/3a345028-610d-4c37-af11-98e95904bfe5/iiif/cam-75-1-v_0000_000001.tif/full/!300,500/0/default.jpg | L31: Livro impresso | M31: Português | O31: Tercetos impressos pela primeira vez, em 1576, na História da Província de Santa Cruz, de Pedro de Magalhães Gandavo | R31: 1.ª ed. | S31: Lisboa : Joaquim Eusébio dos Santos | T31: 1894 | U31: 1894 | V31: 12 p., 1 est. | W31: Camões, Luís de, 1524-1580 | Z31: Braga, Teófilo, 1843-1924, Comentador (em meio audiovisual) | AC31: CAM. 75//1 V. | AD31: CAM500 | AE31: http://id.bnportugal.gov.pt/bib/catbnp/397877 | AF31: Livre
A32: 401648 | B32: 1 | C32: 3 | D32: https://permalinkbnd.bnportugal.gov.pt/viewer/273125/?offset=#page=3&viewer=picture&o=info&n=0&q= | E32: 1, 3 [site] [portada, retrato Camões] | I32: 401648 | J32: https://purl.pt/43662 | K32: https://bndigital.bnportugal.gov.pt//i/?IIIF=/c5/6f/77/dc/c56f77dc-6fe1-4b19-8eac-61a13ea62b02/iiif/cam-64-7-a_0000_000001.tif/full/!300,500/0/default.jpg | L32: Periódico | M32: Português | O32: Plutarcho portuguez | P32: colecção de retratos e biographias dos principaes vultos historicos da civilisação portugueza | R32: 1.ª ed. | S32: Porto : Julio Costa, Emilio Biel | T32: 1881 | U32: 1881 | AC32: J. 1690//7 V. | AD32: CAM500 | AE32: http://id.bnportugal.gov.pt/bib/catbnp/401648 | AF32: Livre
A33: 401658 | B33: 1 | C33: 1 | D33: https://permalinkbnd.bnportugal.gov.pt/viewer/3/?offset=#page=1&viewer=picture&o=info&n=0&q= | E33: 1 | I33: 401658 | J33: https://purl.pt/43862 | K33: https://bndigital.bnportugal.gov.pt//i/?IIIF=/9e/f3/33/17/9ef33317-4c7f-4371-8da7-082d54e2724e/iiif/cam-66-2-a_0001.tif/full/!300,500/0/default.jpg | L33: Livro impresso | M33: Português | O33: Victor Hugo a Camões no 3º centenário | R33: 1.ª ed. | S33: Lisboa : J. Camilo Videira | T33: 1880 | U33: 1880 | AC33: CAM. 66//2 A. | AD33: CAM500 | AE33: http://id.bnportugal.gov.pt/bib/catbnp/401658 | AF33: Livre
A34: 401739 | B34: 1 | C34: 1 | D34: https://permalinkbnd.bnportugal.gov.pt/viewer/274260/?offset=#page=1&viewer=picture&o=info&n=0&q= | E34: 1 | I34: 401739 | J34: https://purl.pt/43865 | K34: https://bndigital.bnportugal.gov.pt//i/?IIIF=/2d/fe/15/07/2dfe1507-1025-44a9-b149-33c026517803/iiif/cam-66-5-a_0001.tif/full/!300,500/0/default.jpg | L34: Livro impresso | M34: Português | O34: Homenagem ao príncipe dos poetas peninsulares ao reconstrutor da língua portuguesa, a Luís de Camões | R34: 1.ª ed. | S34: Lisboa : Emp. Dic. Univ. Português | T34: 1880 | U34: 1880 | V34: 4 p. | AC34: CAM. 66//5 A. | AD34: CAM500 | AE34: http://id.bnportugal.gov.pt/bib/catbnp/401739 | AF34: Livre
A35: 402086 | B35: 1 | C35: 16 | D35: https://permalinkbnd.bnportugal.gov.pt/viewer/274280/?offset=#page=16&viewer=picture&o=info&n=0&q= | E35: 16 [site], 22 | I35: 402086 | J35: https://purl.pt/43891 | K35: https://bndigital.bnportugal.gov.pt//i/?IIIF=/dc/d1/27/77/dcd12777-3117-4eb1-94d0-a5bb23f4e7b6/iiif/cam-69-a_0005.tif/full/!300,500/0/default.jpg | L35: Livro impresso | M35: Português | O35: Collecção Camoneana de José do Canto | P35: tentativa de um catalogo methodico e remissivo | R35: 1.ª ed. | S35: Lisboa : Imprensa Nacional | T35: 1895 | U35: 1895 | V35: XI, 357, 5 p. | W35: Canto, José do, 1820-1898 | Z35: Reis, Jaime Batalha, 1847-1935, Antigo possuidor | AC35: CAM. 69 A. | AD35: CAM500 | AE35: http://id.bnportugal.gov.pt/bib/catbnp/402086 | AF35: Livre
A36: 402086 | B36: 1 | C36: 22 | D36: https://permalinkbnd.bnportugal.gov.pt/viewer/274280/?offset=#page=22&viewer=picture&o=info&n=0&q= | E36: 16 [site], 22 | I36: 402086 | J36: https://purl.pt/43891 | K36: https://bndigital.bnportugal.gov.pt//i/?IIIF=/dc/d1/27/77/dcd12777-3117-4eb1-94d0-a5bb23f4e7b6/iiif/cam-69-a_0005.tif/full/!300,500/0/default.jpg | L36: Livro impresso | M36: Português | O36: Collecção Camoneana de José do Canto | P36: tentativa de um catalogo methodico e remissivo | R36: 1.ª ed. | S36: Lisboa : Imprensa Nacional | T36: 1895 | U36: 1895 | V36: XI, 357, 5 p. | W36: Canto, José do, 1820-1898 | Z36: Reis, Jaime Batalha, 1847-1935, Antigo possuidor | AC36: CAM. 69 A. | AD36: CAM500 | AE36: http://id.bnportugal.gov.pt/bib/catbnp/402086 | AF36: Livre
A37: 402917 | B37: 1 | C37: 9 | D37: https://permalinkbnd.bnportugal.gov.pt/viewer/273560/?offset=#page=9&viewer=picture&o=info&n=0&q= | E37: 9 | I37: 402917 | J37: https://purl.pt/43923 | K37: https://bndigital.bnportugal.gov.pt//i/?IIIF=/68/36/f7/0d/6836f70d-c35f-47cf-856b-993a65ff926c/iiif/cam-130-a_0000_000001.tif/full/!300,500/0/default.jpg | L37: Livro impresso | M37: Português | N37: Alemão | O37: Camoëns in Cintra | P37: (poemeto extrahido do livro Tag und Nachstucke) | R37: 1.ª ed. | S37: Lisboa : M. Gomes, Livreiro-Editor | T37: 1891 | U37: 1891 | V37: 39, 1 p. | W37: Schack, Adolf Friederich Graf von, 1815-1894 | Z37: Camões, Luís de, 1524-1580, Antecedente bibliográfico | AC37: CAM. 71//1 A. | AD37: CAM500 | AE37: http://id.bnportugal.gov.pt/bib/catbnp/402917 | AF37: Livre
A38: 404543 | B38: 1 | C38: 7 | D38: https://permalinkbnd.bnportugal.gov.pt/viewer/273347/?offset=#page=7&viewer=picture&o=info&n=0&q= | E38: 7 | I38: 404543 | J38: https://purl.pt/43827 | K38: https://bndigital.bnportugal.gov.pt//i/?IIIF=/9f/79/bf/47/9f79bf47-41ea-438e-b7e9-2c631c46bb91/iiif/cam-81-a_0000_000001.tif/full/!300,500/0/default.jpg | L38: Livro impresso | M38: Português | O38: Excerptos dos Lusíadas | P38: canto II | R38: 1.ª ed. | S38: Lisboa : Imprensa Nacional | T38: 1889 | U38: 1889 | W38: Camões, Luís de, 1524-1580 | AC38: CAM. 81 A. | AD38: CAM500 | AE38: http://id.bnportugal.gov.pt/bib/catbnp/404543 | AF38: Livre
A39: 404800 | B39: 1 | C39: 21 | D39: https://permalinkbnd.bnportugal.gov.pt/viewer/274348/?offset=#page=21&viewer=picture&o=info&n=0&q= | E39: 3, 21, 69 | I39: 404800 | J39: https://purl.pt/43914 | K39: https://bndigital.bnportugal.gov.pt//i/?IIIF=/1f/06/28/af/1f0628af-b385-4108-b72c-0016b004b60d/iiif/cam-85-a_0003.tif/full/!300,500/0/default.jpg | L39: Livro impresso | M39: Português | O39: Os festejos do centenario da India | P39: grande album commemorativo | R39: 1.ª ed. | S39: Lisboa : publicado pela empreza do Pimpão | T39: 1898 | U39: 1898 | V39: 31 f. | AC39: CAM. 85 A. | AD39: CAM500 | AE39: http://id.bnportugal.gov.pt/bib/catbnp/404800 | AF39: Livre
A40: 404800 | B40: 1 | C40: 69 | D40: https://permalinkbnd.bnportugal.gov.pt/viewer/274348/?offset=#page=69&viewer=picture&o=info&n=0&q= | E40: 3, 21, 69 | I40: 404800 | J40: https://purl.pt/43914 | K40: https://bndigital.bnportugal.gov.pt//i/?IIIF=/1f/06/28/af/1f0628af-b385-4108-b72c-0016b004b60d/iiif/cam-85-a_0003.tif/full/!300,500/0/default.jpg | L40: Livro impresso | M40: Português | O40: Os festejos do centenario da India | P40: grande album commemorativo | R40: 1.ª ed. | S40: Lisboa : publicado pela empreza do Pimpão | T40: 1898 | U40: 1898 | V40: 31 f. | AC40: CAM. 85 A. | AD40: CAM500 | AE40: http://id.bnportugal.gov.pt/bib/catbnp/404800 | AF40: Livre
...

Sheet imagens-partilhar
A1: id | B1: pasta | C1: volume | D1: imagem | E1: purl | F1: imagens_texto | G1: imagens | H1: notas Regina | I1: url_página | J1: Categoria-1 | K1: Categoria-2 | L1: Categoria-3 | M1: url_purl | N1: number | O1: link_pagina | P1: ncb | Q1: purl | R1: capa | S1: tipo de material | T1: língua | U1: língua da obra original | V1: título | W1: subtítulo | X1: título original | Y1: edição | Z1: publicação | AA1: data da publicação | AB1: data da publicação2 | AC1: dimensões | AD1: autor | AE1: autor - organização | AF1: co-autores | AG1: autores secundários | AH1: co-autores - organizações | AI1: autores secundários - organizações | AJ1: cota | AK1: coleção | AL1: id persistente | AM1: acesso | AN1: notas gerais | AO1: notas título | AP1: notas conteúdo | AQ1: sumário | AR1: título uniforme | AS1: título colectivo uniforme | AT1: Column1
A2: 9951 | B2: 367428 | C2: 1 | D2: 1 | E2: https://purl.pt/43428 | F2: 1 | G2: 1 | I2: =HYPERLINK(O2) -> https://permalinkbnd.bnportugal.gov.pt/viewer/272369/?offset=#page=1&viewer=picture&o=info&n=0&q= | M2: https://purl.pt/43428 | N2: 272369 | O2: =CONCATENATE("https://permalinkbnd.bnportugal.gov.pt/viewer/",N2,"/?offset=#page=",D2,"&viewer=picture&o=info&n=0&q=") -> https://permalinkbnd.bnportugal.gov.pt/viewer/272369/?offset=#page=1&viewer=picture&o=info&n=0&q= | P2: 367428 | Q2: https://purl.pt/43428 | R2: https://bndigital.bnportugal.gov.pt//i/?IIIF=/a3/eb/b0/67/a3ebb067-89f3-40ff-a518-1fc158846d4b/iiif/cam-479-p_0003.tif/full/!300,500/0/default.jpg | S2: Livro impresso | T2: Italiano | V2: I Lusiadi | W2: poema | Y2: 1.ª ed. | Z2: Milano : Edoardo Sonzogno,editore | AA2: 1882 | AB2: 1882 | AC2: 196 p. | AD2: Camões, Luís de, 1524-1580 | AG2: Nervi, Antonio, 1760-1836, Tradutor | AJ2: CAM. 479 P. | AK2: CAM500 | AL2: http://id.bnportugal.gov.pt/bib/catbnp/367428 | AM2: Livre
A3: 9968 | B3: 381074 | C3: 1 | D3: 499 | E3: https://purl.pt/43747 | F3: 10 [site], 11, 103 [site pelicano direita], 107, 142, 107, 142, 145, 185, 235, 270 [site assassinato de Inês], 273, 306, 309 [site ninfas], 342, 345, 374, 377, 410, 413, 447, 499, 526 [site apontamento] [pintura de Camões por Columbano, portada, fac-símile do frontispício da 1.ª Ed. de Os Lusíadas, ilustrações da obra] | G3: 10, 11, 103, 145, 235, 270, 273, 306, 309, 342, 345, 374, 377, 410, 413, 447, 499 | I3: =HYPERLINK(O3) -> https://permalinkbnd.bnportugal.gov.pt/viewer/274089/?offset=#page=499&viewer=picture&o=info&n=0&q= | M3: https://purl.pt/43747 | N3: 274089 | O3: =CONCATENATE("https://permalinkbnd.bnportugal.gov.pt/viewer/",N3,"/?offset=#page=",D3,"&viewer=picture&o=info&n=0&q=") -> https://permalinkbnd.bnportugal.gov.pt/viewer/274089/?offset=#page=499&viewer=picture&o=info&n=0&q= | P3: 381074 | Q3: https://purl.pt/43747 | R3: https://bndigital.bnportugal.gov.pt//i/?IIIF=/7d/bb/9c/38/7dbb9c38-ff88-4f0e-8125-42d713ee62f7/iiif/cam-21-a_0007.tif/full/!300,500/0/default.jpg | S3: Livro impresso | T3: Português | V3: Os Lusíadas | W3: edição consagrada a comemorar o terceiro centenário do poeta... | Y3: 1.ª ed. | Z3: Lisboa : Of. de Castro Irmão | AA3: 1880 | AB3: 1880 | AC3: XCIII, 422 p., 1 il. | AD3: Camões, Luís de, 1524-1580 | AG3: Coelho, Adolfo, 1847-1919, Revisor ; Ortigão, Ramalho, 1836-1915, Autor da introdução, etc. ; Montoro, Reinaldo Carlos, 1831-?, Autor da introdução, etc. | AI3: Gabinete Português de Leitura, Editor literário | AJ3: L. 94571 V. | AK3: CAM500 | AL3: http://id.bnportugal.gov.pt/bib/catbnp/381074 | AM3: Livre
A4: 9993 | B4: 381465 | C4: 1 | D4: 644 | E4: https://purl.pt/43233 | F4: 5 [site], 10 [site], 11 [site], 43, 46 [Vasco da Gama], 47, 100, 101, 160, 161, 163, 235, 237, 289, 291 [site Adamastor], 293, 343 [site apontamento livros e pena], 345, 347, 397, 443, 445, 495 [site Mercúrio, caduceu e navegador], 545 [site máquina do mundo], 547, 625, 627, 644 [monge com livro] [portadas, retrato de Camões, fotogravuras em cada Canto] | G4: 5, 10, 11, 43, 46 , 47, 101, 160, 161, 163, 235, 237, 291, 293, 343, 345, 347, 397, 443, 445, 495 , 545, 547, 627, 644 | I4: =HYPERLINK(O4) -> https://permalinkbnd.bnportugal.gov.pt/viewer/271573/?offset=#page=644&viewer=picture&o=info&n=0&q= | M4: https://purl.pt/43233 | N4: 271573 | O4: =CONCATENATE("https://permalinkbnd.bnportugal.gov.pt/viewer/",N4,"/?offset=#page=",D4,"&viewer=picture&o=info&n=0&q=") -> https://permalinkbnd.bnportugal.gov.pt/viewer/271573/?offset=#page=644&viewer=picture&o=info&n=0&q= | P4: 381465 | Q4: https://purl.pt/43233 | R4: https://bndigital.bnportugal.gov.pt//i/?IIIF=/1b/9b/a2/7b/1b9ba27b-8449-49d7-b8fa-ec3081a88a08/iiif/cam-30-a_0000_000005.tif/full/!300,500/0/default.jpg | S4: Livro impresso | T4: Português | V4: Os Lusíadas | W4: profusamente illustrada com desenhos allegoricos... | Y4: 1.ª ed. | Z4: Lisboa : Silvestre Castanheiro | AA4: 1898 | AB4: 1898 | AC4: XXXIII, 599 p. | AD4: Camões, Luís de, 1524-1580 | AG4: Belo, António Mendes, 1842-1929, Comentador (em meio audiovisual) ; Chagas, Pinheiro, 1842-1895, Comentador (em meio audiovisual) ; Costa, José Fernandes, 1848-1920, Comentador (em meio audiovisual) | AJ4: L. 5864 A. | AK4: CAM500 | AL4: http://id.bnportugal.gov.pt/bib/catbnp/381465 | AM4: Livre
A5: 9994 | B5: 381468 | C5: 1 | D5: 8 | E5: https://purl.pt/43745 | F5: 8 [site retrato de Camões] | G5: 8 | I5: =HYPERLINK(O5) -> https://permalinkbnd.bnportugal.gov.pt/viewer/274087/?offset=#page=8&viewer=picture&o=info&n=0&q= | M5: https://purl.pt/43745 | N5: 274087 | O5: =CONCATENATE("https://permalinkbnd.bnportugal.gov.pt/viewer/",N5,"/?offset=#page=",D5,"&viewer=picture&o=info&n=0&q=") -> https://permalinkbnd.bnportugal.gov.pt/viewer/274087/?offset=#page=8&viewer=picture&o=info&n=0&q= | P5: 381468 | Q5: https://purl.pt/43745 | R5: https://bndigital.bnportugal.gov.pt//i/?IIIF=/e0/20/89/c0/e02089c0-dfb3-4507-bf34-b897aa5b2b44/iiif/cam-33-a_0009.tif/full/!300,500/0/default.jpg | S5: Livro impresso | T5: Espanhol | U5: Português | V5: Os Lusiadas (Los Portugueses) | Y5: Edicion acompañada del legitimo texto portugues y de copiosas notas y noticias biograficas sobre el insigne poeta ibero | Z5: Badajoz : Establecimiento Tipográfico de José Santamaría | AA5: 1873 | AB5: 1873 | AC5: 263, 1 p. | AD5: Camões, Luís de, 1524-1580 | AG5: Soler y Arqués, Carlos, 1836-1896, Tradutor | AJ5: CAM. 33 A. | AK5: CAM500 | AL5: http://id.bnportugal.gov.pt/bib/catbnp/381468 | AM5: Livre
A6: 9995 | B6: 381701 | C6: 1 | D6: 11 | E6: https://purl.pt/43724 | F6: 11 | G6: 11 | I6: =HYPERLINK(O6) -> https://permalinkbnd.bnportugal.gov.pt/viewer/281141/?offset=#page=11&viewer=picture&o=info&n=0&q= | M6: https://purl.pt/43724 | N6: 281141 | O6: =CONCATENATE("https://permalinkbnd.bnportugal.gov.pt/viewer/",N6,"/?offset=#page=",D6,"&viewer=picture&o=info&n=0&q=") -> https://permalinkbnd.bnportugal.gov.pt/viewer/281141/?offset=#page=11&viewer=picture&o=info&n=0&q= | P6: 381701 | Q6: https://purl.pt/43724 | R6: https://bndigital.bnportugal.gov.pt//i/?IIIF=/58/a8/a6/57/58a8a657-7fb2-4700-9b55-408036c37806/iiif/cam-40-a_0001.tif/full/!300,500/0/default.jpg | S6: Livro impresso | T6: Poliglota | U6: Português | V6: Inês de Castro | W6: episódio extraído do canto terceiro do poema épico Os Lusíadas | Y6: 1.ª ed. | Z6: Lisboa : Imprensa Nacional | AA6: 1873 | AB6: 1873 | AC6: 76 p. | AD6: Camões, Luís de, 1524-1580 | AJ6: CAM. 40 A. | AK6: CAM500 | AL6: http://id.bnportugal.gov.pt/bib/catbnp/381701 | AM6: Livre
A7: 9998 | B7: 381889 | C7: 1 | D7: 1 | E7: https://purl.pt/43659 | F7: 1 [Inês de Castro, Vasco da Gama, Catarina de Ataíde e retrato de Camões] | G7: 1 | I7: =HYPERLINK(O7) -> https://permalinkbnd.bnportugal.gov.pt/viewer/273118/?offset=#page=1&viewer=picture&o=info&n=0&q= | M7: https://purl.pt/43659 | N7: 273118 | O7: =CONCATENATE("https://permalinkbnd.bnportugal.gov.pt/viewer/",N7,"/?offset=#page=",D7,"&viewer=picture&o=info&n=0&q=") -> https://permalinkbnd.bnportugal.gov.pt/viewer/273118/?offset=#page=1&viewer=picture&o=info&n=0&q= | P7: 381889 | Q7: https://purl.pt/43659 | R7: https://bndigital.bnportugal.gov.pt//i/?IIIF=/5b/91/40/8a/5b91408a-4af1-4a94-bccc-2d03ee894a1c/iiif/cam-44-2-a_0000_000001.tif/full/!300,500/0/default.jpg | S7: Periódico | T7: Português | V7: Pérolas de Camões | W7: publicação dedicada ao povo | Y7: 1.ª ed. | Z7: Lisboa : Lallement Fréres | AA7: 1880 | AB7: 1880 | AI7: Lallement Frères, Editor comercial | AJ7: CAM. 44//2 A. | AK7: CAM500 | AL7: http://id.bnportugal.gov.pt/bib/catbnp/381889 | AM7: Livre
A8: 9999 | B8: 381903 | C8: 1 | D8: 5 | E8: https://purl.pt/42920 | F8: 5 [1.º] | G8: 5 | I8: =HYPERLINK(O8) -> https://permalinkbnd.bnportugal.gov.pt/viewer/270037/?offset=#page=5&viewer=picture&o=info&n=0&q= | M8: https://purl.pt/42920 | N8: 270037 | O8: =CONCATENATE("https://permalinkbnd.bnportugal.gov.pt/viewer/",N8,"/?offset=#page=",D8,"&viewer=picture&o=info&n=0&q=") -> https://permalinkbnd.bnportugal.gov.pt/viewer/270037/?offset=#page=5&viewer=picture&o=info&n=0&q= | P8: 381903 | Q8: https://purl.pt/42920 | R8: https://bndigital.bnportugal.gov.pt//i/?IIIF=/84/00/0c/50/84000c50-b90e-4a7c-aa5e-5cb3dfef4dab/iiif/cam-45-2-a_0000_000001.tif/full/!300,500/0/default.jpg | S8: Periódico | T8: Polaco | V8: Illustrowane Tygedniowe | Y8: 1.ª ed. | AA8: 1880 | AB8: 1880 | AJ8: CAM. 45//2 A. | AK8: CAM500 | AL8: http://id.bnportugal.gov.pt/bib/catbnp/381903 | AM8: Livre
A9: 10000 | B9: 382749 | C9: 1 | D9: 7 | E9: https://purl.pt/42835 | F9: 7 [site], 19, 23 [frisos site, esta obra contém mais apontamentos e frisos belíssimos] | I9: =HYPERLINK(O9) -> https://permalinkbnd.bnportugal.gov.pt/viewer/270109/?offset=#page=7&viewer=picture&o=info&n=0&q= | M9: https://purl.pt/42835 | N9: 270109 | O9: =CONCATENATE("https://permalinkbnd.bnportugal.gov.pt/viewer/",N9,"/?offset=#page=",D9,"&viewer=picture&o=info&n=0&q=") -> https://permalinkbnd.bnportugal.gov.pt/viewer/270109/?offset=#page=7&viewer=picture&o=info&n=0&q= | P9: 382749 | Q9: https://purl.pt/42835 | R9: https://bndigital.bnportugal.gov.pt//i/?IIIF=/60/58/22/4f/6058224f-9454-448f-8489-96a3a71253f5/iiif/cam-47-a_0000_000007.tif/full/!300,500/0/default.jpg | S9: Livro impresso | T9: Português | V9: Pretidão de amor | W9: endechas a Bárbara escrava seguidas da respectiva tradução em várias línguas... | Y9: 1.ª ed. | Z9: Lisboa : Imprensa Nacional | AA9: 1893 | AB9: 1893 | AC9: 2 v. | AD9: Camões, Luís de, 1524-1580 | AG9: Cunha, Xavier da, 1840-1920, Autor da introdução, etc. | AJ9: CAM. 270 V. | AK9: CAM500 | AL9: http://id.bnportugal.gov.pt/bib/catbnp/382749 | AM9: Livre
A10: 10003 | B10: 382749 | C10: 1 | D10: 19 | E10: https://purl.pt/42835 | I10: =HYPERLINK(O10) -> https://permalinkbnd.bnportugal.gov.pt/viewer/270109/?offset=#page=19&viewer=picture&o=info&n=0&q= | M10: https://purl.pt/42835 | N10: 270109 | O10: =CONCATENATE("https://permalinkbnd.bnportugal.gov.pt/viewer/",N10,"/?offset=#page=",D10,"&viewer=picture&o=info&n=0&q=") -> https://permalinkbnd.bnportugal.gov.pt/viewer/270109/?offset=#page=19&viewer=picture&o=info&n=0&q= | P10: 382749 | Q10: https://purl.pt/42835 | R10: https://bndigital.bnportugal.gov.pt//i/?IIIF=/60/58/22/4f/6058224f-9454-448f-8489-96a3a71253f5/iiif/cam-47-a_0000_000007.tif/full/!300,500/0/default.jpg | S10: Livro impresso | T10: Português | V10: Pretidão de amor | W10: endechas a Bárbara escrava seguidas da respectiva tradução em várias línguas... | Y10: 1.ª ed. | Z10: Lisboa : Imprensa Nacional | AA10: 1893 | AB10: 1893 | AC10: 2 v. | AD10: Camões, Luís de, 1524-1580 | AG10: Cunha, Xavier da, 1840-1920, Autor da introdução, etc. | AJ10: CAM. 270 V. | AK10: CAM500 | AL10: http://id.bnportugal.gov.pt/bib/catbnp/382749 | AM10: Livre
B11: 382749 | C11: 1 | D11: 23 | E11: https://purl.pt/42835 | I11: =HYPERLINK(O11) -> https://permalinkbnd.bnportugal.gov.pt/viewer/270109/?offset=#page=23&viewer=picture&o=info&n=0&q= | M11: https://purl.pt/42835 | N11: 270109 | O11: =CONCATENATE("https://permalinkbnd.bnportugal.gov.pt/viewer/",N11,"/?offset=#page=",D11,"&viewer=picture&o=info&n=0&q=") -> https://permalinkbnd.bnportugal.gov.pt/viewer/270109/?offset=#page=23&viewer=picture&o=info&n=0&q= | P11: 382749 | Q11: https://purl.pt/42835 | R11: https://bndigital.bnportugal.gov.pt//i/?IIIF=/60/58/22/4f/6058224f-9454-448f-8489-96a3a71253f5/iiif/cam-47-a_0000_000007.tif/full/!300,500/0/default.jpg | S11: Livro impresso | T11: Português | V11: Pretidão de amor | W11: endechas a Bárbara escrava seguidas da respectiva tradução em várias línguas... | Y11: 1.ª ed. | Z11: Lisboa : Imprensa Nacional | AA11: 1893 | AB11: 1893 | AC11: 2 v. | AD11: Camões, Luís de, 1524-1580 | AG11: Cunha, Xavier da, 1840-1920, Autor da introdução, etc. | AJ11: CAM. 270 V. | AK11: CAM500 | AL11: http://id.bnportugal.gov.pt/bib/catbnp/382749 | AM11: Livre
B12: 382834 | C12: 1 | D12: 11 | E12: https://purl.pt/43815 | F12: 11 [caravela com Vasco da Gama] | G12: 11 | I12: =HYPERLINK(O12) -> https://permalinkbnd.bnportugal.gov.pt/viewer/273316/?offset=#page=11&viewer=picture&o=info&n=0&q= | M12: https://purl.pt/43815 | N12: 273316 | O12: =CONCATENATE("https://permalinkbnd.bnportugal.gov.pt/viewer/",N12,"/?offset=#page=",D12,"&viewer=picture&o=info&n=0&q=") -> https://permalinkbnd.bnportugal.gov.pt/viewer/273316/?offset=#page=11&viewer=picture&o=info&n=0&q= | P12: 382834 | Q12: https://purl.pt/43815 | R12: https://bndigital.bnportugal.gov.pt//i/?IIIF=/b6/d0/71/c6/b6d071c6-e05d-4c17-96b2-07a62e35fb7f/iiif/cam-82-1-v_0000_000005.tif/full/!300,500/0/default.jpg | S12: Livro impresso | T12: Português | V12: Comemoração gloriosa da morte de Luiz de Camões 10 de Junho de 1889 | Y12: 1.ª ed. | Z12: Evora : Minerva Eborense de J. José Baptista, Rua d'Aviz | AA12: 1889 | AB12: 1889 | AC12: 12, 4 p. | AD12: Barata, António Francisco, 1836-1910 | AG12: Camões, Luís de, 1524-1580, Antecedente bibliográfico | AJ12: CAM. 309//13 V. | AK12: CAM500 | AL12: http://id.bnportugal.gov.pt/bib/catbnp/382834 | AM12: Livre
A13: 10004 | B13: 382844 | C13: 1 | D13: 3 | E13: https://purl.pt/43227 | F13: 3 | I13: =HYPERLINK(O13) -> https://permalinkbnd.bnportugal.gov.pt/viewer/271559/?offset=#page=3&viewer=picture&o=info&n=0&q= | M13: https://purl.pt/43227 | N13: 271559 | O13: =CONCATENATE("https://permalinkbnd.bnportugal.gov.pt/viewer/",N13,"/?offset=#page=",D13,"&viewer=picture&o=info&n=0&q=") -> https://permalinkbnd.bnportugal.gov.pt/viewer/271559/?offset=#page=3&viewer=picture&o=info&n=0&q= | P13: 382844 | Q13: https://purl.pt/43227 | R13: https://bndigital.bnportugal.gov.pt//i/?IIIF=/be/12/df/5e/be12df5e-248d-4e0b-823f-bb93ea5db616/iiif/cam-2058-v_0001.tif/full/!300,500/0/default.jpg | S13: Livro impresso | T13: Português | V13: A Luiz de Camões | W13: com notas curiosas e tres ineditos do poeta | Y13: 1.ª ed. | Z13: Evora : Tip. Minerva, de A.F. Barata | AA13: 1880 | AB13: 1880 | AC13: 24 p. | AD13: Barata, António Francisco, 1836-1910 | AG13: Camões, Luís de, 1524-1580, Antecedente bibliográfico | AJ13: L. 599//32 A. | AK13: CAM500 | AL13: http://id.bnportugal.gov.pt/bib/catbnp/382844 | AM13: Livre
A14: 10005 | B14: 382955 | C14: 1 | D14: 6 | E14: https://purl.pt/43816 | F14: 6 [site, retrato do Poeta laureado] | G14: 6 | I14: =HYPERLINK(O14) -> https://permalinkbnd.bnportugal.gov.pt/viewer/274171/?offset=#page=6&viewer=picture&o=info&n=0&q= | M14: https://purl.pt/43816 | N14: 274171 | O14: =CONCATENATE("https://permalinkbnd.bnportugal.gov.pt/viewer/",N14,"/?offset=#page=",D14,"&viewer=picture&o=info&n=0&q=") -> https://permalinkbnd.bnportugal.gov.pt/viewer/274171/?offset=#page=6&viewer=picture&o=info&n=0&q= | P14: 382955 | Q14: https://purl.pt/43816 | R14: https://bndigital.bnportugal.gov.pt//i/?IIIF=/df/8e/1b/e5/df8e1be5-0f74-4fdb-9b58-5bfa696ca99d/iiif/cam-53-5-a_0001.tif/full/!300,500/0/default.jpg | S14: Livro impresso | T14: Português | V14: Auto da cunhagem da medalha comemorativa das festas da Grande Comissão Portuense... | Y14: 1.ª ed. | Z14: Porto : s. n. | AA14: 1880 | AB14: 1880 | AE14: Grande Comissão Portuense | AG14: Camões, Luís de, 1524-1580, Antecedente bibliográfico | AJ14: CAM. 53//5 A. | AK14: CAM500 | AL14: http://id.bnportugal.gov.pt/bib/catbnp/382955 | AM14: Livre
A15: 10007 | B15: 382972 | C15: 1 | D15: 14 | E15: https://purl.pt/43819 | F15: 14 [site, imagem da medalha/gravura comemorativa do monumento erigido à memória do Poeta] | G15: 14 | I15: =HYPERLINK(O15) -> https://permalinkbnd.bnportugal.gov.pt/viewer/274229/?offset=#page=14&viewer=picture&o=info&n=0&q= | M15: https://purl.pt/43819 | N15: 274229 | O15: =CONCATENATE("https://permalinkbnd.bnportugal.gov.pt/viewer/",N15,"/?offset=#page=",D15,"&viewer=picture&o=info&n=0&q=") -> https://permalinkbnd.bnportugal.gov.pt/viewer/274229/?offset=#page=14&viewer=picture&o=info&n=0&q= | P15: 382972 | Q15: https://purl.pt/43819 | R15: https://bndigital.bnportugal.gov.pt//i/?IIIF=/80/3b/b9/df/803bb9df-b4de-496a-adbc-25a9d95b3638/iiif/cam-55-a_0007.tif/full/!300,500/0/default.jpg | S15: Livro impresso | T15: Português | V15: Surrexit | W15: homenagem a Luís de Camões | Y15: 1.ª ed. | Z15: Lisboa : Imprensa Nacional | AA15: 1880 | AB15: 1880 | AD15: Ribeiro, Tomás, 1831-1901 | AJ15: CAM. 55 A. | AK15: CAM500 | AL15: http://id.bnportugal.gov.pt/bib/catbnp/382972 | AM15: Livre
A16: 10008 | B16: 382978 | C16: 1 | D16: 7 | E16: https://purl.pt/43823 | F16: 7 [site], 13 [site, itinerário do cortejo triunfal], 15 [site préstito cívico e triunfal] | G16: 7, 13, 15 | I16: =HYPERLINK(O16) -> https://permalinkbnd.bnportugal.gov.pt/viewer/274235/?offset=#page=7&viewer=picture&o=info&n=0&q= | M16: https://purl.pt/43823 | N16: 274235 | O16: =CONCATENATE("https://permalinkbnd.bnportugal.gov.pt/viewer/",N16,"/?offset=#page=",D16,"&viewer=picture&o=info&n=0&q=") -> https://permalinkbnd.bnportugal.gov.pt/viewer/274235/?offset=#page=7&viewer=picture&o=info&n=0&q= | P16: 382978 | Q16: https://purl.pt/43823 | R16: https://bndigital.bnportugal.gov.pt//i/?IIIF=/8a/04/06/d1/8a0406d1-dcdf-40af-9ba2-5fa354405f51/iiif/cam-56-a_0001.tif/full/!300,500/0/default.jpg | S16: Livro impresso | T16: Português | V16: Programa da celebração em Lisboa do terceiro centenário de Luís de Camões | W16: comemoração promovida pela imprensa jornalística auxiliada pela Câmara Municipal | Y16: 1.ª ed. | Z16: Lisboa : Tip. Universal | AA16: 1880 | AB16: 1880 | AC16: 8 p. | AG16: Camões, Luís de, 1524-1580, Antecedente bibliográfico | AJ16: CAM. 134 A. | AK16: CAM500 | AL16: http://id.bnportugal.gov.pt/bib/catbnp/382978 | AM16: Livre
A17: 10009 | B17: 382978 | C17: 1 | D17: 13 | E17: https://purl.pt/43823 | F17: 7 [site], 13 [site, itinerário do cortejo triunfal], 15 [site préstito cívico e triunfal] | G17: 7, 13, 15 | I17: =HYPERLINK(O17) -> https://permalinkbnd.bnportugal.gov.pt/viewer/274235/?offset=#page=13&viewer=picture&o=info&n=0&q= | M17: https://purl.pt/43823 | N17: 274235 | O17: =CONCATENATE("https://permalinkbnd.bnportugal.gov.pt/viewer/",N17,"/?offset=#page=",D17,"&viewer=picture&o=info&n=0&q=") -> https://permalinkbnd.bnportugal.gov.pt/viewer/274235/?offset=#page=13&viewer=picture&o=info&n=0&q= | P17: 382978 | Q17: https://purl.pt/43823 | R17: https://bndigital.bnportugal.gov.pt//i/?IIIF=/8a/04/06/d1/8a0406d1-dcdf-40af-9ba2-5fa354405f51/iiif/cam-56-a_0001.tif/full/!300,500/0/default.jpg | S17: Livro impresso | T17: Português | V17: Programa da celebração em Lisboa do terceiro centenário de Luís de Camões | W17: comemoração promovida pela imprensa jornalística auxiliada pela Câmara Municipal | Y17: 1.ª ed. | Z17: Lisboa : Tip. Universal | AA17: 1880 | AB17: 1880 | AC17: 8 p. | AG17: Camões, Luís de, 1524-1580, Antecedente bibliográfico | AJ17: CAM. 134 A. | AK17: CAM500 | AL17: http://id.bnportugal.gov.pt/bib/catbnp/382978 | AM17: Livre
A18: 10010 | B18: 382978 | C18: 1 | D18: 15 | E18: https://purl.pt/43823 | F18: 7 [site], 13 [site, itinerário do cortejo triunfal], 15 [site préstito cívico e triunfal] | G18: 7, 13, 15 | I18: =HYPERLINK(O18) -> https://permalinkbnd.bnportugal.gov.pt/viewer/274235/?offset=#page=15&viewer=picture&o=info&n=0&q= | M18: https://purl.pt/43823 | N18: 274235 | O18: =CONCATENATE("https://permalinkbnd.bnportugal.gov.pt/viewer/",N18,"/?offset=#page=",D18,"&viewer=picture&o=info&n=0&q=") -> https://permalinkbnd.bnportugal.gov.pt/viewer/274235/?offset=#page=15&viewer=picture&o=info&n=0&q= | P18: 382978 | Q18: https://purl.pt/43823 | R18: https://bndigital.bnportugal.gov.pt//i/?IIIF=/8a/04/06/d1/8a0406d1-dcdf-40af-9ba2-5fa354405f51/iiif/cam-56-a_0001.tif/full/!300,500/0/default.jpg | S18: Livro impresso | T18: Português | V18: Programa da celebração em Lisboa do terceiro centenário de Luís de Camões | W18: comemoração promovida pela imprensa jornalística auxiliada pela Câmara Municipal | Y18: 1.ª ed. | Z18: Lisboa : Tip. Universal | AA18: 1880 | AB18: 1880 | AC18: 8 p. | AG18: Camões, Luís de, 1524-1580, Antecedente bibliográfico | AJ18: CAM. 134 A. | AK18: CAM500 | AL18: http://id.bnportugal.gov.pt/bib/catbnp/382978 | AM18: Livre
A19: 10011 | B19: 382981 | C19: 1 | D19: 9 | E19: https://purl.pt/43818 | F19: 9 | I19: =HYPERLINK(O19) -> https://permalinkbnd.bnportugal.gov.pt/viewer/1880/?offset=#page=9&viewer=picture&o=info&n=0&q= | M19: https://purl.pt/43818 | N19: 1880 | O19: =CONCATENATE("https://permalinkbnd.bnportugal.gov.pt/viewer/",N19,"/?offset=#page=",D19,"&viewer=picture&o=info&n=0&q=") -> https://permalinkbnd.bnportugal.gov.pt/viewer/1880/?offset=#page=9&viewer=picture&o=info&n=0&q= | P19: 382981 | Q19: https://purl.pt/43818 | R19: https://bndigital.bnportugal.gov.pt//i/?IIIF=/2b/2d/51/1b/2b2d511b-4290-4cc3-b338-dffc6cbedad2/iiif/cam-57-a_0001.tif/full/!300,500/0/default.jpg | S19: Livro impresso | T19: Português | V19: Relatório da Directoria do Gabinete de Leitura do Rio de Janeiro em 1880 | Y19: 1.ª ed. | Z19: Rio de Janeiro : Tip e lit. Moreira Maximino | AA19: 1881 | AB19: 1881 | AI19: Real Gabinete Português de Leitura do Rio de Janeiro | AJ19: CAM. 57 A. | AK19: CAM500 | AL19: http://id.bnportugal.gov.pt/bib/catbnp/382981 | AM19: Livre
A20: 10013 | B20: 385945 | C20: 1 | D20: 15 | E20: https://purl.pt/43873 | F20: 10 [fotografia do autor], 11 [portada], 15 | G20: 15 | I20: =HYPERLINK(O20) -> https://permalinkbnd.bnportugal.gov.pt/viewer/273149/?offset=#page=15&viewer=picture&o=info&n=0&q= | M20: https://purl.pt/43873 | N20: 273149 | O20: =CONCATENATE("https://permalinkbnd.bnportugal.gov.pt/viewer/",N20,"/?offset=#page=",D20,"&viewer=picture&o=info&n=0&q=") -> https://permalinkbnd.bnportugal.gov.pt/viewer/273149/?offset=#page=15&viewer=picture&o=info&n=0&q= | P20: 385945 | Q20: https://purl.pt/43873 | R20: https://bndigital.bnportugal.gov.pt//i/?IIIF=/ca/5d/8c/c5/ca5d8cc5-b85c-4f76-893f-7de2d31a6d43/iiif/cam-63-a_0000_000007.tif/full/!300,500/0/default.jpg | S20: Livro impresso | T20: Poliglota | U20: Português | V20: Álbum literário comemorativo do terceiro centenário de Luís de Camões | Y20: 1.ª ed. | Z20: Porto : Tip. Ocidental | AA20: 1880 | AB20: 1880 | AC20: 28 p. | AG20: Esteves, Francisco Xavier, 1864-1944, Editor literário | AJ20: CAM. 133 A. | AK20: CAM500 | AL20: http://id.bnportugal.gov.pt/bib/catbnp/385945 | AM20: Livre
A21: 10014 | B21: 385949 | C21: 1 | D21: 1 | E21: https://purl.pt/43866 | F21: 1 | G21: 1 | I21: =HYPERLINK(O21) -> https://permalinkbnd.bnportugal.gov.pt/viewer/274256/?offset=#page=1&viewer=picture&o=info&n=0&q= | M21: https://purl.pt/43866 | N21: 274256 | O21: =CONCATENATE("https://permalinkbnd.bnportugal.gov.pt/viewer/",N21,"/?offset=#page=",D21,"&viewer=picture&o=info&n=0&q=") -> https://permalinkbnd.bnportugal.gov.pt/viewer/274256/?offset=#page=1&viewer=picture&o=info&n=0&q= | P21: 385949 | Q21: https://purl.pt/43866 | R21: https://bndigital.bnportugal.gov.pt//i/?IIIF=/06/33/d8/97/0633d897-92cc-4a30-beb0-aa004a6f6470/iiif/cam-64-1-a_0001.tif/full/!300,500/0/default.jpg | S21: Livro impresso | T21: Português | V21: Homenagem a Camões | W21: Luís de Camões e a nacionalidade portuguesa | Y21: 1.ª ed. | Z21: São Miguel : s. n. | AA21: 1880 | AB21: 1880 | AE21: Centro Republicano Federal de Ponta Delgada | AJ21: CAM. 64//1 A. | AK21: CAM500 | AL21: http://id.bnportugal.gov.pt/bib/catbnp/385949 | AM21: Livre
A22: 10015 | B22: 386935 | C22: 1 | D22: 1 | E22: https://purl.pt/43871 | F22: 1 | I22: =HYPERLINK(O22) -> https://permalinkbnd.bnportugal.gov.pt/viewer/273122/?offset=#page=1&viewer=picture&o=info&n=0&q= | M22: https://purl.pt/43871 | N22: 273122 | O22: =CONCATENATE("https://permalinkbnd.bnportugal.gov.pt/viewer/",N22,"/?offset=#page=",D22,"&viewer=picture&o=info&n=0&q=") -> https://permalinkbnd.bnportugal.gov.pt/viewer/273122/?offset=#page=1&viewer=picture&o=info&n=0&q= | P22: 386935 | Q22: https://purl.pt/43871 | R22: https://bndigital.bnportugal.gov.pt//i/?IIIF=/c8/18/91/78/c8189178-5871-4300-9edd-154703c6e75a/iiif/cam-64-3-a_0000_000001.tif/full/!300,500/0/default.jpg | S22: Livro impresso | T22: Português | V22: Vianna a Camões | W22: comemoração do tricentenário do imortal cantor dos Lusíadas | Y22: 1.ª ed. | Z22: Viana do Castelo : André Jorge Pereira & Filho | AA22: 1880 | AB22: 1880 | AJ22: CAM. 64//3 A. | AK22: CAM500 | AL22: http://id.bnportugal.gov.pt/bib/catbnp/386935 | AM22: Livre
A23: 10016 | B23: 386992 | C23: 1 | D23: 1 | E23: https://purl.pt/43661 | F23: 1 | G23: 1 | I23: =HYPERLINK(O23) -> https://permalinkbnd.bnportugal.gov.pt/viewer/273124/?offset=#page=1&viewer=picture&o=info&n=0&q= | M23: https://purl.pt/43661 | N23: 273124 | O23: =CONCATENATE("https://permalinkbnd.bnportugal.gov.pt/viewer/",N23,"/?offset=#page=",D23,"&viewer=picture&o=info&n=0&q=") -> https://permalinkbnd.bnportugal.gov.pt/viewer/273124/?offset=#page=1&viewer=picture&o=info&n=0&q= | P23: 386992 | Q23: https://purl.pt/43661 | R23: https://bndigital.bnportugal.gov.pt//i/?IIIF=/0c/53/05/58/0c530558-6907-414a-974d-e379f3070104/iiif/cam-64-4-a_0000_000001.tif/full/!300,500/0/default.jpg | S23: Livro impresso | T23: Português | V23: Homenagem da Sociedade Amizade, Recreio e Ínstrução | Y23: 1.ª ed. | Z23: S. Miguel : Lit. dos Açores | AA23: 1880 | AB23: 1880 | AG23: Camões, Luís de, 1524-1580, Antecedente bibliográfico | AI23: Sociedade Amizade Recreio e Ínstrução | AJ23: CAM. 64//4 A. | AK23: CAM500 | AL23: http://id.bnportugal.gov.pt/bib/catbnp/386992 | AM23: Livre
A24: 10019 | B24: 396405 | C24: 1 | D24: 1 | E24: https://purl.pt/6115 | F24: 1 | G24: 1 | I24: =HYPERLINK(O24) -> https://permalinkbnd.bnportugal.gov.pt/viewer/36059/?offset=#page=1&viewer=picture&o=info&n=0&q= | M24: https://purl.pt/6115 | N24: 36059 | O24: =CONCATENATE("https://permalinkbnd.bnportugal.gov.pt/viewer/",N24,"/?offset=#page=",D24,"&viewer=picture&o=info&n=0&q=") -> https://permalinkbnd.bnportugal.gov.pt/viewer/36059/?offset=#page=1&viewer=picture&o=info&n=0&q= | P24: 396405 | Q24: https://purl.pt/6115 | R24: https://bndigital.bnportugal.gov.pt//i/?IIIF=/11/21/33/35/11213335-0c6f-4347-8501-397d47049e54/iiif/e-2172-v_0000_1-2_p24-C-R0150_000001.tif/full/!300,500/0/default.jpg | S24: Iconografia | T24: Português | V24: Luís de Camões | Y24: 1.ª ed. | Z24: Macau : Com. Org. Comem. Dia de Portugal de Camões e das Comunid. Portuguesas | AA24: 1992 | AB24: 1992 | AC24: 1 imagem | AD24: Fialho, Fernando Jorge, 1965- | AJ24: PURL 6115/0 | AL24: http://id.bnportugal.gov.pt/bib/catbnp/396405 | AM24: Interno
