Workbook

Sheet Folha1
A1: pasta | B1: volume | C1: imagem | D1: purl-hiperligação | E1: purl 2 | F1: n bnd | G1: l1 | H1: l2 | I1: l3 | J1: l4 | K1: imagens_texto | L1: Notas - Isabel Almeida | M1: link página | N1: l5 | O1: l6 | P1: link imagem | Q1: nada | R1: url_página | S1: nada 2 | T1: imagens | U1: notas Regina | V1: notas Regina 2 | W1: tem JPG
A2: 367428 | B2: 1 | C2: 1 | D2: https://purl.pt/43428 | E2: https://purl.pt/43428 | F2: 272369 | G2: https://permalinkbnd.bnportugal.gov.pt/viewer/ | H2: /?offset=#page= | I2: &viewer=picture&o=info&n=0&q= | J2: =CONCATENATE(G2,F2,H2,C2,I2) -> https://permalinkbnd.bnportugal.gov.pt/viewer/272369/?offset=#page=1&viewer=picture&o=info&n=0&q= | K2: 1 | L2: =VLOOKUP(A2,Folha2!$A$2:$B$2019,2,FALSE) -> I Lusiadi. Antonio Nervi, 1882. Trad. Paratextos vida. Trad. Paratextos notas (de rodapé em cada Canto). Trad. Paratextos argumentos. | M2: =HYPERLINK(J2) -> https://permalinkbnd.bnportugal.gov.pt/viewer/272369/?offset=#page=1&viewer=picture&o=info&n=0&q= | N2: C:\Users\mbaptista\OneDrive - Biblioteca Nacional de Portugal\Documentos\python\camoniana\imagens\capas\ | O2: =CONCATENATE(N2,A2,"\",B2,"\",C2,".jpg") -> C:\Users\mbaptista\OneDrive - Biblioteca Nacional de Portugal\Documentos\python\camoniana\imagens\capas\367428\1\1.jpg | P2: =HYPERLINK(O2) -> C:\Users\mbaptista\OneDrive - Biblioteca Nacional de Portugal\Documentos\python\camoniana\imagens\capas\367428\1\1.jpg | R2: https://permalinkbnd.bnportugal.gov.pt/viewer/272369/?offset=#page=1&viewer=picture&o=info&n=0&q= | T2: 1 | W2: Sim
A3: 381074 | B3: 1 | C3: 10 | D3: https://purl.pt/43747 | E3: https://purl.pt/43747 | F3: 274089 | G3: https://permalinkbnd.bnportugal.gov.pt/viewer/ | H3: /?offset=#page= | I3: &viewer=picture&o=info&n=0&q= | J3: =CONCATENATE(G3,F3,H3,C3,I3) -> https://permalinkbnd.bnportugal.gov.pt/viewer/274089/?offset=#page=10&viewer=picture&o=info&n=0&q= | K3: 10 [site], 11, 103 [site pelicano direita], 107, 142, 107, 142, 145, 185, 235, 270 [site assassinato de Inês], 273, 306, 309 [site ninfas], 342, 345, 374, 377, 410, 413, 447, 499, 526 [site apontamento] [pintura de Camões por Columbano, portada, fac-símile do frontispício da 1.ª Ed. de Os Lusíadas, ilustrações da obra] | L3: =VLOOKUP(A3,Folha2!$A$2:$B$2019,2,FALSE) -> Os Lusíadas, Rio de Janeiro, 1880, sem argumentos. | M3: =HYPERLINK(J3) -> https://permalinkbnd.bnportugal.gov.pt/viewer/274089/?offset=#page=10&viewer=picture&o=info&n=0&q= | N3: C:\Users\mbaptista\OneDrive - Biblioteca Nacional de Portugal\Documentos\python\camoniana\imagens\capas\ | O3: =CONCATENATE(N3,A3,"\",B3,"\",C3,".jpg") -> C:\Users\mbaptista\OneDrive - Biblioteca Nacional de Portugal\Documentos\python\camoniana\imagens\capas\381074\1\10.jpg | P3: =HYPERLINK(O3) -> C:\Users\mbaptista\OneDrive - Biblioteca Nacional de Portugal\Documentos\python\camoniana\imagens\capas\381074\1\10.jpg | T3: 10, 11, 103, 145, 235, 270, 273, 306, 309, 342, 345, 374, 377, 410, 413, 447, 499
A4: 381074 | B4: 1 | C4: 11 | D4: https://purl.pt/43747 | E4: https://purl.pt/43747 | F4: 274089 | G4: https://permalinkbnd.bnportugal.gov.pt/viewer/ | H4: /?offset=#page= | I4: &viewer=picture&o=info&n=0&q= | J4: =CONCATENATE(G4,F4,H4,C4,I4) -> https://permalinkbnd.bnportugal.gov.pt/viewer/274089/?offset=#page=11&viewer=picture&o=info&n=0&q= | K4: 10 [site], 11, 103 [site pelicano direita], 107, 142, 107, 142, 145, 185, 235, 270 [site assassinato de Inês], 273, 306, 309 [site ninfas], 342, 345, 374, 377, 410, 413, 447, 499, 526 [site apontamento] [pintura de Camões por Columbano, portada, fac-símile do frontispício da 1.ª Ed. de Os Lusíadas, ilustrações da obra] | L4: =VLOOKUP(A4,Folha2!$A$2:$B$2019,2,FALSE) -> Os Lusíadas, Rio de Janeiro, 1880, sem argumentos. | M4: =HYPERLINK(J4) -> https://permalinkbnd.bnportugal.gov.pt/viewer/274089/?offset=#page=11&viewer=picture&o=info&n=0&q= | N4: C:\Users\mbaptista\OneDrive - Biblioteca Nacional de Portugal\Documentos\python\camoniana\imagens\capas\ | O4: =CONCATENATE(N4,A4,"\",B4,"\",C4,".jpg") -> C:\Users\mbaptista\OneDrive - Biblioteca Nacional de Portugal\Documentos\python\camoniana\imagens\capas\381074\1\11.jpg | P4: =HYPERLINK(O4) -> C:\Users\mbaptista\OneDrive - Biblioteca Nacional de Portugal\Documentos\python\camoniana\imagens\capas\381074\1\11.jpg | T4: 10, 11, 103, 145, 235, 270, 273, 306, 309, 342, 345, 374, 377, 410, 413, 447, 499
A5: 381074 | B5: 1 | C5: 103 | D5: https://purl.pt/43747 | E5: https://purl.pt/43747 | F5: 274089 | G5: https://permalinkbnd.bnportugal.gov.pt/viewer/ | H5: /?offset=#page= | I5: &viewer=picture&o=info&n=0&q= | J5: =CONCATENATE(G5,F5,H5,C5,I5) -> https://permalinkbnd.bnportugal.gov.pt/viewer/274089/?offset=#page=103&viewer=picture&o=info&n=0&q= | K5: 10 [site], 11, 103 [site pelicano direita], 107, 142, 107, 142, 145, 185, 235, 270 [site assassinato de Inês], 273, 306, 309 [site ninfas], 342, 345, 374, 377, 410, 413, 447, 499, 526 [site apontamento] [pintura de Camões por Columbano, portada, fac-símile do frontispício da 1.ª Ed. de Os Lusíadas, ilustrações da obra] | L5: =VLOOKUP(A5,Folha2!$A$2:$B$2019,2,FALSE) -> Os Lusíadas, Rio de Janeiro, 1880, sem argumentos. | M5: =HYPERLINK(J5) -> https://permalinkbnd.bnportugal.gov.pt/viewer/274089/?offset=#page=103&viewer=picture&o=info&n=0&q= | N5: C:\Users\mbaptista\OneDrive - Biblioteca Nacional de Portugal\Documentos\python\camoniana\imagens\capas\ | O5: =CONCATENATE(N5,A5,"\",B5,"\",C5,".jpg") -> C:\Users\mbaptista\OneDrive - Biblioteca Nacional de Portugal\Documentos\python\camoniana\imagens\capas\381074\1\103.jpg | P5: =HYPERLINK(O5) -> C:\Users\mbaptista\OneDrive - Biblioteca Nacional de Portugal\Documentos\python\camoniana\imagens\capas\381074\1\103.jpg | T5: 10, 11, 103, 145, 235, 270, 273, 306, 309, 342, 345, 374, 377, 410, 413, 447, 499
A6: 381074 | B6: 1 | C6: 107 | D6: https://purl.pt/43747 | E6: https://purl.pt/43747 | F6: 274089 | G6: https://permalinkbnd.bnportugal.gov.pt/viewer/ | H6: /?offset=#page= | I6: &viewer=picture&o=info&n=0&q= | J6: =CONCATENATE(G6,F6,H6,C6,I6) -> https://permalinkbnd.bnportugal.gov.pt/viewer/274089/?offset=#page=107&viewer=picture&o=info&n=0&q= | K6: 10 [site], 11, 103 [site pelicano direita], 107, 142, 107, 142, 145, 185, 235, 270 [site assassinato de Inês], 273, 306, 309 [site ninfas], 342, 345, 374, 377, 410, 413, 447, 499, 526 [site apontamento] [pintura de Camões por Columbano, portada, fac-símile do frontispício da 1.ª Ed. de Os Lusíadas, ilustrações da obra] | L6: =VLOOKUP(A6,Folha2!$A$2:$B$2019,2,FALSE) -> Os Lusíadas, Rio de Janeiro, 1880, sem argumentos. | M6: =HYPERLINK(J6) -> https://permalinkbnd.bnportugal.gov.pt/viewer/274089/?offset=#page=107&viewer=picture&o=info&n=0&q= | N6: C:\Users\mbaptista\OneDrive - Biblioteca Nacional de Portugal\Documentos\python\camoniana\imagens\capas\ | O6: =CONCATENATE(N6,A6,"\",B6,"\",C6,".jpg") -> C:\Users\mbaptista\OneDrive - Biblioteca Nacional de Portugal\Documentos\python\camoniana\imagens\capas\381074\1\107.jpg | P6: =HYPERLINK(O6) -> C:\Users\mbaptista\OneDrive - Biblioteca Nacional de Portugal\Documentos\python\camoniana\imagens\capas\381074\1\107.jpg | T6: 10, 11, 103, 145, 235, 270, 273, 306, 309, 342, 345, 374, 377, 410, 413, 447, 499
A7: 381074 | B7: 1 | C7: 142 | D7: https://purl.pt/43747 | E7: https://purl.pt/43747 | F7: 274089 | G7: https://permalinkbnd.bnportugal.gov.pt/viewer/ | H7: /?offset=#page= | I7: &viewer=picture&o=info&n=0&q= | J7: =CONCATENATE(G7,F7,H7,C7,I7) -> https://permalinkbnd.bnportugal.gov.pt/viewer/274089/?offset=#page=142&viewer=picture&o=info&n=0&q= | K7: 10 [site], 11, 103 [site pelicano direita], 107, 142, 107, 142, 145, 185, 235, 270 [site assassinato de Inês], 273, 306, 309 [site ninfas], 342, 345, 374, 377, 410, 413, 447, 499, 526 [site apontamento] [pintura de Camões por Columbano, portada, fac-símile do frontispício da 1.ª Ed. de Os Lusíadas, ilustrações da obra] | L7: =VLOOKUP(A7,Folha2!$A$2:$B$2019,2,FALSE) -> Os Lusíadas, Rio de Janeiro, 1880, sem argumentos. | M7: =HYPERLINK(J7) -> https://permalinkbnd.bnportugal.gov.pt/viewer/274089/?offset=#page=142&viewer=picture&o=info&n=0&q= | N7: C:\Users\mbaptista\OneDrive - Biblioteca Nacional de Portugal\Documentos\python\camoniana\imagens\capas\ | O7: =CONCATENATE(N7,A7,"\",B7,"\",C7,".jpg") -> C:\Users\mbaptista\OneDrive - Biblioteca Nacional de Portugal\Documentos\python\camoniana\imagens\capas\381074\1\142.jpg | P7: =HYPERLINK(O7) -> C:\Users\mbaptista\OneDrive - Biblioteca Nacional de Portugal\Documentos\python\camoniana\imagens\capas\381074\1\142.jpg | T7: 10, 11, 103, 145, 235, 270, 273, 306, 309, 342, 345, 374, 377, 410, 413, 447, 499
A8: 381074 | B8: 1 | C8: 107 | D8: https://purl.pt/43747 | E8: https://purl.pt/43747 | F8: 274089 | G8: https://permalinkbnd.bnportugal.gov.pt/viewer/ | H8: /?offset=#page= | I8: &viewer=picture&o=info&n=0&q= | J8: =CONCATENATE(G8,F8,H8,C8,I8) -> https://permalinkbnd.bnportugal.gov.pt/viewer/274089/?offset=#page=107&viewer=picture&o=info&n=0&q= | K8: 10 [site], 11, 103 [site pelicano direita], 107, 142, 107, 142, 145, 185, 235, 270 [site assassinato de Inês], 273, 306, 309 [site ninfas], 342, 345, 374, 377, 410, 413, 447, 499, 526 [site apontamento] [pintura de Camões por Columbano, portada, fac-símile do frontispício da 1.ª Ed. de Os Lusíadas, ilustrações da obra] | L8: =VLOOKUP(A8,Folha2!$A$2:$B$2019,2,FALSE) -> Os Lusíadas, Rio de Janeiro, 1880, sem argumentos. | M8: =HYPERLINK(J8) -> https://permalinkbnd.bnportugal.gov.pt/viewer/274089/?offset=#page=107&viewer=picture&o=info&n=0&q= | N8: C:\Users\mbaptista\OneDrive - Biblioteca Nacional de Portugal\Documentos\python\camoniana\imagens\capas\ | O8: =CONCATENATE(N8,A8,"\",B8,"\",C8,".jpg") -> C:\Users\mbaptista\OneDrive - Biblioteca Nacional de Portugal\Documentos\python\camoniana\imagens\capas\381074\1\107.jpg | P8: =HYPERLINK(O8) -> C:\Users\mbaptista\OneDrive - Biblioteca Nacional de Portugal\Documentos\python\camoniana\imagens\capas\381074\1\107.jpg | T8: 10, 11, 103, 145, 235, 270, 273, 306, 309, 342, 345, 374, 377, 410, 413, 447, 499
A9: 381074 | B9: 1 | C9: 142 | D9: https://purl.pt/43747 | E9: https://purl.pt/43747 | F9: 274089 | G9: https://permalinkbnd.bnportugal.gov.pt/viewer/ | H9: /?offset=#page= | I9: &viewer=picture&o=info&n=0&q= | J9: =CONCATENATE(G9,F9,H9,C9,I9) -> https://permalinkbnd.bnportugal.gov.pt/viewer/274089/?offset=#page=142&viewer=picture&o=info&n=0&q= | K9: 10 [site], 11, 103 [site pelicano direita], 107, 142, 107, 142, 145, 185, 235, 270 [site assassinato de Inês], 273, 306, 309 [site ninfas], 342, 345, 374, 377, 410, 413, 447, 499, 526 [site apontamento] [pintura de Camões por Columbano, portada, fac-símile do frontispício da 1.ª Ed. de Os Lusíadas, ilustrações da obra] | L9: =VLOOKUP(A9,Folha2!$A$2:$B$2019,2,FALSE) -> Os Lusíadas, Rio de Janeiro, 1880, sem argumentos. | M9: =HYPERLINK(J9) -> https://permalinkbnd.bnportugal.gov.pt/viewer/274089/?offset=#page=142&viewer=picture&o=info&n=0&q= | N9: C:\Users\mbaptista\OneDrive - Biblioteca Nacional de Portugal\Documentos\python\camoniana\imagens\capas\ | O9: =CONCATENATE(N9,A9,"\",B9,"\",C9,".jpg") -> C:\Users\mbaptista\OneDrive - Biblioteca Nacional de Portugal\Documentos\python\camoniana\imagens\capas\381074\1\142.jpg | P9: =HYPERLINK(O9) -> C:\Users\mbaptista\OneDrive - Biblioteca Nacional de Portugal\Documentos\python\camoniana\imagens\capas\381074\1\142.jpg | T9: 10, 11, 103, 145, 235, 270, 273, 306, 309, 342, 345, 374, 377, 410, 413, 447, 499
A10: 381074 | B10: 1 | C10: 145 | D10: https://purl.pt/43747 | E10: https://purl.pt/43747 | F10: 274089 | G10: https://permalinkbnd.bnportugal.gov.pt/viewer/ | H10: /?offset=#page= | I10: &viewer=picture&o=info&n=0&q= | J10: =CONCATENATE(G10,F10,H10,C10,I10) -> https://permalinkbnd.bnportugal.gov.pt/viewer/274089/?offset=#page=145&viewer=picture&o=info&n=0&q= | K10: 10 [site], 11, 103 [site pelicano direita], 107, 142, 107, 142, 145, 185, 235, 270 [site assassinato de Inês], 273, 306, 309 [site ninfas], 342, 345, 374, 377, 410, 413, 447, 499, 526 [site apontamento] [pintura de Camões por Columbano, portada, fac-símile do frontispício da 1.ª Ed. de Os Lusíadas, ilustrações da obra] | L10: =VLOOKUP(A10,Folha2!$A$2:$B$2019,2,FALSE) -> Os Lusíadas, Rio de Janeiro, 1880, sem argumentos. | M10: =HYPERLINK(J10) -> https://permalinkbnd.bnportugal.gov.pt/viewer/274089/?offset=#page=145&viewer=picture&o=info&n=0&q= | N10: C:\Users\mbaptista\OneDrive - Biblioteca Nacional de Portugal\Documentos\python\camoniana\imagens\capas\ | O10: =CONCATENATE(N10,A10,"\",B10,"\",C10,".jpg") -> C:\Users\mbaptista\OneDrive - Biblioteca Nacional de Portugal\Documentos\python\camoniana\imagens\capas\381074\1\145.jpg | P10: =HYPERLINK(O10) -> C:\Users\mbaptista\OneDrive - Biblioteca Nacional de Portugal\Documentos\python\camoniana\imagens\capas\381074\1\145.jpg | T10: 10, 11, 103, 145, 235, 270, 273, 306, 309, 342, 345, 374, 377, 410, 413, 447, 499
A11: 381074 | B11: 1 | C11: 185 | D11: https://purl.pt/43747 | E11: https://purl.pt/43747 | F11: 274089 | G11: https://permalinkbnd.bnportugal.gov.pt/viewer/ | H11: /?offset=#page= | I11: &viewer=picture&o=info&n=0&q= | J11: =CONCATENATE(G11,F11,H11,C11,I11) -> https://permalinkbnd.bnportugal.gov.pt/viewer/274089/?offset=#page=185&viewer=picture&o=info&n=0&q= | K11: 10 [site], 11, 103 [site pelicano direita], 107, 142, 107, 142, 145, 185, 235, 270 [site assassinato de Inês], 273, 306, 309 [site ninfas], 342, 345, 374, 377, 410, 413, 447, 499, 526 [site apontamento] [pintura de Camões por Columbano, portada, fac-símile do frontispício da 1.ª Ed. de Os Lusíadas, ilustrações da obra] | L11: =VLOOKUP(A11,Folha2!$A$2:$B$2019,2,FALSE) -> Os Lusíadas, Rio de Janeiro, 1880, sem argumentos. | M11: =HYPERLINK(J11) -> https://permalinkbnd.bnportugal.gov.pt/viewer/274089/?offset=#page=185&viewer=picture&o=info&n=0&q= | N11: C:\Users\mbaptista\OneDrive - Biblioteca Nacional de Portugal\Documentos\python\camoniana\imagens\capas\ | O11: =CONCATENATE(N11,A11,"\",B11,"\",C11,".jpg") -> C:\Users\mbaptista\OneDrive - Biblioteca Nacional de Portugal\Documentos\python\camoniana\imagens\capas\381074\1\185.jpg | P11: =HYPERLINK(O11) -> C:\Users\mbaptista\OneDrive - Biblioteca Nacional de Portugal\Documentos\python\camoniana\imagens\capas\381074\1\185.jpg | T11: 10, 11, 103, 145, 235, 270, 273, 306, 309, 342, 345, 374, 377, 410, 413, 447, 499
A12: 381074 | B12: 1 | C12: 235 | D12: https://purl.pt/43747 | E12: https://purl.pt/43747 | F12: 274089 | G12: https://permalinkbnd.bnportugal.gov.pt/viewer/ | H12: /?offset=#page= | I12: &viewer=picture&o=info&n=0&q= | J12: =CONCATENATE(G12,F12,H12,C12,I12) -> https://permalinkbnd.bnportugal.gov.pt/viewer/274089/?offset=#page=235&viewer=picture&o=info&n=0&q= | K12: 10 [site], 11, 103 [site pelicano direita], 107, 142, 107, 142, 145, 185, 235, 270 [site assassinato de Inês], 273, 306, 309 [site ninfas], 342, 345, 374, 377, 410, 413, 447, 499, 526 [site apontamento] [pintura de Camões por Columbano, portada, fac-símile do frontispício da 1.ª Ed. de Os Lusíadas, ilustrações da obra] | L12: =VLOOKUP(A12,Folha2!$A$2:$B$2019,2,FALSE) -> Os Lusíadas, Rio de Janeiro, 1880, sem argumentos. | M12: =HYPERLINK(J12) -> https://permalinkbnd.bnportugal.gov.pt/viewer/274089/?offset=#page=235&viewer=picture&o=info&n=0&q= | N12: C:\Users\mbaptista\OneDrive - Biblioteca Nacional de Portugal\Documentos\python\camoniana\imagens\capas\ | O12: =CONCATENATE(N12,A12,"\",B12,"\",C12,".jpg") -> C:\Users\mbaptista\OneDrive - Biblioteca Nacional de Portugal\Documentos\python\camoniana\imagens\capas\381074\1\235.jpg | P12: =HYPERLINK(O12) -> C:\Users\mbaptista\OneDrive - Biblioteca Nacional de Portugal\Documentos\python\camoniana\imagens\capas\381074\1\235.jpg | T12: 10, 11, 103, 145, 235, 270, 273, 306, 309, 342, 345, 374, 377, 410, 413, 447, 499
A13: 381074 | B13: 1 | C13: 270 | D13: https://purl.pt/43747 | E13: https://purl.pt/43747 | F13: 274089 | G13: https://permalinkbnd.bnportugal.gov.pt/viewer/ | H13: /?offset=#page= | I13: &viewer=picture&o=info&n=0&q= | J13: =CONCATENATE(G13,F13,H13,C13,I13) -> https://permalinkbnd.bnportugal.gov.pt/viewer/274089/?offset=#page=270&viewer=picture&o=info&n=0&q= | K13: 10 [site], 11, 103 [site pelicano direita], 107, 142, 107, 142, 145, 185, 235, 270 [site assassinato de Inês], 273, 306, 309 [site ninfas], 342, 345, 374, 377, 410, 413, 447, 499, 526 [site apontamento] [pintura de Camões por Columbano, portada, fac-símile do frontispício da 1.ª Ed. de Os Lusíadas, ilustrações da obra] | L13: =VLOOKUP(A13,Folha2!$A$2:$B$2019,2,FALSE) -> Os Lusíadas, Rio de Janeiro, 1880, sem argumentos. | M13: =HYPERLINK(J13) -> https://permalinkbnd.bnportugal.gov.pt/viewer/274089/?offset=#page=270&viewer=picture&o=info&n=0&q= | N13: C:\Users\mbaptista\OneDrive - Biblioteca Nacional de Portugal\Documentos\python\camoniana\imagens\capas\ | O13: =CONCATENATE(N13,A13,"\",B13,"\",C13,".jpg") -> C:\Users\mbaptista\OneDrive - Biblioteca Nacional de Portugal\Documentos\python\camoniana\imagens\capas\381074\1\270.jpg | P13: =HYPERLINK(O13) -> C:\Users\mbaptista\OneDrive - Biblioteca Nacional de Portugal\Documentos\python\camoniana\imagens\capas\381074\1\270.jpg | T13: 10, 11, 103, 145, 235, 270, 273, 306, 309, 342, 345, 374, 377, 410, 413, 447, 499
A14: 381074 | B14: 1 | C14: 273 | D14: https://purl.pt/43747 | E14: https://purl.pt/43747 | F14: 274089 | G14: https://permalinkbnd.bnportugal.gov.pt/viewer/ | H14: /?offset=#page= | I14: &viewer=picture&o=info&n=0&q= | J14: =CONCATENATE(G14,F14,H14,C14,I14) -> https://permalinkbnd.bnportugal.gov.pt/viewer/274089/?offset=#page=273&viewer=picture&o=info&n=0&q= | K14: 10 [site], 11, 103 [site pelicano direita], 107, 142, 107, 142, 145, 185, 235, 270 [site assassinato de Inês], 273, 306, 309 [site ninfas], 342, 345, 374, 377, 410, 413, 447, 499, 526 [site apontamento] [pintura de Camões por Columbano, portada, fac-símile do frontispício da 1.ª Ed. de Os Lusíadas, ilustrações da obra] | L14: =VLOOKUP(A14,Folha2!$A$2:$B$2019,2,FALSE) -> Os Lusíadas, Rio de Janeiro, 1880, sem argumentos. | M14: =HYPERLINK(J14) -> https://permalinkbnd.bnportugal.gov.pt/viewer/274089/?offset=#page=273&viewer=picture&o=info&n=0&q= | N14: C:\Users\mbaptista\OneDrive - Biblioteca Nacional de Portugal\Documentos\python\camoniana\imagens\capas\ | O14: =CONCATENATE(N14,A14,"\",B14,"\",C14,".jpg") -> C:\Users\mbaptista\OneDrive - Biblioteca Nacional de Portugal\Documentos\python\camoniana\imagens\capas\381074\1\273.jpg | P14: =HYPERLINK(O14) -> C:\Users\mbaptista\OneDrive - Biblioteca Nacional de Portugal\Documentos\python\camoniana\imagens\capas\381074\1\273.jpg | T14: 10, 11, 103, 145, 235, 270, 273, 306, 309, 342, 345, 374, 377, 410, 413, 447, 499
... A23: 381074 | B23: 1 | C23: 447 | D23: https://purl.pt/43747 | E23: https://purl.pt/43747 | F23: 274089 | G23: https://permalinkbnd.bnportugal.gov.pt/viewer/ | H23: /?offset=#page= | I23: &viewer=picture&o=info&n=0&q= | J23: =CONCATENATE(G23,F23,H23,C23,I23) -> https://permalinkbnd.bnportugal.gov.pt/viewer/274089/?offset=#page=447&viewer=picture&o=info&n=0&q= | K23: 10 [site], 11, 103 [site pelicano direita], 107, 142, 107, 142, 145, 185, 235, 270 [site assassinato de Inês], 273, 306, 309 [site ninfas], 342, 345, 374, 377, 410, 413, 447, 499, 526 [site apontamento] [pintura de Camões por Columbano, portada, fac-símile do frontispício da 1.ª Ed. de Os Lusíadas, ilustrações da obra] | L23: =VLOOKUP(A23,Folha2!$A$2:$B$2019,2,FALSE) -> Os Lusíadas, Rio de Janeiro, 1880, sem argumentos. | M23: =HYPERLINK(J23) -> https://permalinkbnd.bnportugal.gov.pt/viewer/274089/?offset=#page=447&viewer=picture&o=info&n=0&q= | N23: C:\Users\mbaptista\OneDrive - Biblioteca Nacional de Portugal\Documentos\python\camoniana\imagens\capas\ | O23: =CONCATENATE(N23,A23,"\",B23,"\",C23,".jpg") -> C:\Users\mbaptista\OneDrive - Biblioteca Nacional de Portugal\Documentos\python\camoniana\imagens\capas\381074\1\447.jpg | P23: =HYPERLINK(O23) -> C:\Users\mbaptista\OneDrive - Biblioteca Nacional de Portugal\Documentos\python\camoniana\imagens\capas\381074\1\447.jpg | T23: 10, 11, 103, 145, 235, 270, 273, 306, 309, 342, 345, 374, 377, 410, 413, 447, 499
A24: 381074 | B24: 1 | C24: 499 | D24: https://purl.pt/43747 | E24: https://purl.pt/43747 | F24: 274089 | G24: https://permalinkbnd.bnportugal.gov.pt/viewer/ | H24: /?offset=#page= | I24: &viewer=picture&o=info&n=0&q= | J24: =CONCATENATE(G24,F24,H24,C24,I24) -> https://permalinkbnd.bnportugal.gov.pt/viewer/274089/?offset=#page=499&viewer=picture&o=info&n=0&q= | K24: 10 [site], 11, 103 [site pelicano direita], 107, 142, 107, 142, 145, 185, 235, 270 [site assassinato de Inês], 273, 306, 309 [site ninfas], 342, 345, 374, 377, 410, 413, 447, 499, 526 [site apontamento] [pintura de Camões por Columbano, portada, fac-símile do frontispício da 1.ª Ed. de Os Lusíadas, ilustrações da obra] | L24: =VLOOKUP(A24,Folha2!$A$2:$B$2019,2,FALSE) -> Os Lusíadas, Rio de Janeiro, 1880, sem argumentos. | M24: =HYPERLINK(J24) -> https://permalinkbnd.bnportugal.gov.pt/viewer/274089/?offset=#page=499&viewer=picture&o=info&n=0&q= | N24: C:\Users\mbaptista\OneDrive - Biblioteca Nacional de Portugal\Documentos\python\camoniana\imagens\capas\ | O24: =CONCATENATE(N24,A24,"\",B24,"\",C24,".jpg") -> C:\Users\mbaptista\OneDrive - Biblioteca Nacional de Portugal\Documentos\python\camoniana\imagens\capas\381074\1\499.jpg | P24: =HYPERLINK(O24) -> C:\Users\mbaptista\OneDrive - Biblioteca Nacional de Portugal\Documentos\python\camoniana\imagens\capas\381074\1\499.jpg | R24: https://permalinkbnd.bnportugal.gov.pt/viewer/274089/?offset=#page=499&viewer=picture&o=info&n=0&q= | T24: 10, 11, 103, 145, 235, 270, 273, 306, 309, 342, 345, 374, 377, 410, 413, 447, 499 | W24: Sim
A25: 381074 | B25: 1 | C25: 526 | D25: https://purl.pt/43747 | E25: https://purl.pt/43747 | F25: 274089 | G25: https://permalinkbnd.bnportugal.gov.pt/viewer/ | H25: /?offset=#page= | I25: &viewer=picture&o=info&n=0&q= | J25: =CONCATENATE(G25,F25,H25,C25,I25) -> https://permalinkbnd.bnportugal.gov.pt/viewer/274089/?offset=#page=526&viewer=picture&o=info&n=0&q= | K25: 10 [site], 11, 103 [site pelicano direita], 107, 142, 107, 142, 145, 185, 235, 270 [site assassinato de Inês], 273, 306, 309 [site ninfas], 342, 345, 374, 377, 410, 413, 447, 499, 526 [site apontamento] [pintura de Camões por Columbano, portada, fac-símile do frontispício da 1.ª Ed. de Os Lusíadas, ilustrações da obra] | L25: =VLOOKUP(A25,Folha2!$A$2:$B$2019,2,FALSE) -> Os Lusíadas, Rio de Janeiro, 1880, sem argumentos. | M25: =HYPERLINK(J25) -> https://permalinkbnd.bnportugal.gov.pt/viewer/274089/?offset=#page=526&viewer=picture&o=info&n=0&q= | N25: C:\Users\mbaptista\OneDrive - Biblioteca Nacional de Portugal\Documentos\python\camoniana\imagens\capas\ | O25: =CONCATENATE(N25,A25,"\",B25,"\",C25,".jpg") -> C:\Users\mbaptista\OneDrive - Biblioteca Nacional de Portugal\Documentos\python\camoniana\imagens\capas\381074\1\526.jpg | P25: =HYPERLINK(O25) -> C:\Users\mbaptista\OneDrive - Biblioteca Nacional de Portugal\Documentos\python\camoniana\imagens\capas\381074\1\526.jpg | T25: 10, 11, 103, 145, 235, 270, 273, 306, 309, 342, 345, 374, 377, 410, 413, 447, 499
A26: 381465 | C26: 5 | D26: https://purl.pt/43233 | E26: https://purl.pt/43233 | F26: 271573 | G26: https://permalinkbnd.bnportugal.gov.pt/viewer/ | H26: /?offset=#page= | I26: &viewer=picture&o=info&n=0&q= | J26: =CONCATENATE(G26,F26,H26,C26,I26) -> https://permalinkbnd.bnportugal.gov.pt/viewer/271573/?offset=#page=5&viewer=picture&o=info&n=0&q= | K26: 5 [site], 10 [site], 11 [site], 43, 46 [Vasco da Gama], 47, 100, 101, 160, 161, 163, 235, 237, 289, 291 [site Adamastor], 293, 343 [site apontamento livros e pena], 345, 347, 397, 443, 445, 495 [site Mercúrio, caduceu e navegador], 545 [site máquina do mundo], 547, 625, 627, 644 [monge com livro] [portadas, retrato de Camões, fotogravuras em cada Canto] | L26: =VLOOKUP(A26,Folha2!$A$2:$B$2019,2,FALSE) -> Os Lusíadas, 1898, obra dedicada à Comissão do Centenário e nos paratextos é referida a Celebração: Celebrações (1880); Paratextos argumentos e Iconografia figuras históricas. | M26: =HYPERLINK(J26) -> https://permalinkbnd.bnportugal.gov.pt/viewer/271573/?offset=#page=5&viewer=picture&o=info&n=0&q= | N26: C:\Users\mbaptista\OneDrive - Biblioteca Nacional de Portugal\Documentos\python\camoniana\imagens\capas\ | O26: =CONCATENATE(N26,A26,"\",B26,"\",C26,".jpg") -> C:\Users\mbaptista\OneDrive - Biblioteca Nacional de Portugal\Documentos\python\camoniana\imagens\capas\381465\\5.jpg | P26: =HYPERLINK(O26) -> C:\Users\mbaptista\OneDrive - Biblioteca Nacional de Portugal\Documentos\python\camoniana\imagens\capas\381465\\5.jpg | T26: 5, 10, 11, 43, 46 , 47, 101, 160, 161, 163, 235, 237, 291, 293, 343, 345, 347, 397, 443, 445, 495 , 545, 547, 627, 644
A27: 381465 | C27: 10 | D27: https://purl.pt/43233 | E27: https://purl.pt/43233 | F27: 271573 | G27: https://permalinkbnd.bnportugal.gov.pt/viewer/ | H27: /?offset=#page= | I27: &viewer=picture&o=info&n=0&q= | J27: =CONCATENATE(G27,F27,H27,C27,I27) -> https://permalinkbnd.bnportugal.gov.pt/viewer/271573/?offset=#page=10&viewer=picture&o=info&n=0&q= | K27: 5 [site], 10 [site], 11 [site], 43, 46 [Vasco da Gama], 47, 100, 101, 160, 161, 163, 235, 237, 289, 291 [site Adamastor], 293, 343 [site apontamento livros e pena], 345, 347, 397, 443, 445, 495 [site Mercúrio, caduceu e navegador], 545 [site máquina do mundo], 547, 625, 627, 644 [monge com livro] [portadas, retrato de Camões, fotogravuras em cada Canto] | L27: =VLOOKUP(A27,Folha2!$A$2:$B$2019,2,FALSE) -> Os Lusíadas, 1898, obra dedicada à Comissão do Centenário e nos paratextos é referida a Celebração: Celebrações (1880); Paratextos argumentos e Iconografia figuras históricas. | M27: =HYPERLINK(J27) -> https://permalinkbnd.bnportugal.gov.pt/viewer/271573/?offset=#page=10&viewer=picture&o=info&n=0&q= | N27: C:\Users\mbaptista\OneDrive - Biblioteca Nacional de Portugal\Documentos\python\camoniana\imagens\capas\ | O27: =CONCATENATE(N27,A27,"\",B27,"\",C27,".jpg") -> C:\Users\mbaptista\OneDrive - Biblioteca Nacional de Portugal\Documentos\python\camoniana\imagens\capas\381465\\10.jpg | P27: =HYPERLINK(O27) -> C:\Users\mbaptista\OneDrive - Biblioteca Nacional de Portugal\Documentos\python\camoniana\imagens\capas\381465\\10.jpg | T27: 5, 10, 11, 43, 46 , 47, 101, 160, 161, 163, 235, 237, 291, 293, 343, 345, 347, 397, 443, 445, 495 , 545, 547, 627, 644
A28: 381465 | C28: 43 | D28: https://purl.pt/43233 | E28: https://purl.pt/43233 | F28: 271573 | G28: https://permalinkbnd.bnportugal.gov.pt/viewer/ | H28: /?offset=#page= | I28: &viewer=picture&o=info&n=0&q= | J28: =CONCATENATE(G28,F28,H28,C28,I28) -> https://permalinkbnd.bnportugal.gov.pt/viewer/271573/?offset=#page=43&viewer=picture&o=info&n=0&q= | K28: 5 [site], 10 [site], 11 [site], 43, 46 [Vasco da Gama], 47, 100, 101, 160, 161, 163, 235, 237, 289, 291 [site Adamastor], 293, 343 [site apontamento livros e pena], 345, 347, 397, 443, 445, 495 [site Mercúrio, caduceu e navegador], 545 [site máquina do mundo], 547, 625, 627, 644 [monge com livro] [portadas, retrato de Camões, fotogravuras em cada Canto] | L28: =VLOOKUP(A28,Folha2!$A$2:$B$2019,2,FALSE) -> Os Lusíadas, 1898, obra dedicada à Comissão do Centenário e nos paratextos é referida a Celebração: Celebrações (1880); Paratextos argumentos e Iconografia figuras históricas. | M28: =HYPERLINK(J28) -> https://permalinkbnd.bnportugal.gov.pt/viewer/271573/?offset=#page=43&viewer=picture&o=info&n=0&q= | N28: C:\Users\mbaptista\OneDrive - Biblioteca Nacional de Portugal\Documentos\python\camoniana\imagens\capas\ | O28: =CONCATENATE(N28,A28,"\",B28,"\",C28,".jpg") -> C:\Users\mbaptista\OneDrive - Biblioteca Nacional de Portugal\Documentos\python\camoniana\imagens\capas\381465\\43.jpg | P28: =HYPERLINK(O28) -> C:\Users\mbaptista\OneDrive - Biblioteca Nacional de Portugal\Documentos\python\camoniana\imagens\capas\381465\\43.jpg | T28: 5, 10, 11, 43, 46 , 47, 101, 160, 161, 163, 235, 237, 291, 293, 343, 345, 347, 397, 443, 445, 495 , 545, 547, 627, 644
A29: 381465 | C29: 46 | D29: https://purl.pt/43233 | E29: https://purl.pt/43233 | F29: 271573 | G29: https://permalinkbnd.bnportugal.gov.pt/viewer/ | H29: /?offset=#page= | I29: &viewer=picture&o=info&n=0&q= | J29: =CONCATENATE(G29,F29,H29,C29,I29) -> https://permalinkbnd.bnportugal.gov.pt/viewer/271573/?offset=#page=46&viewer=picture&o=info&n=0&q= | K29: 5 [site], 10 [site], 11 [site], 43, 46 [Vasco da Gama], 47, 100, 101, 160, 161, 163, 235, 237, 289, 291 [site Adamastor], 293, 343 [site apontamento livros e pena], 345, 347, 397, 443, 445, 495 [site Mercúrio, caduceu e navegador], 545 [site máquina do mundo], 547, 625, 627, 644 [monge com livro] [portadas, retrato de Camões, fotogravuras em cada Canto] | L29: =VLOOKUP(A29,Folha2!$A$2:$B$2019,2,FALSE) -> Os Lusíadas, 1898, obra dedicada à Comissão do Centenário e nos paratextos é referida a Celebração: Celebrações (1880); Paratextos argumentos e Iconografia figuras históricas. | M29: =HYPERLINK(J29) -> https://permalinkbnd.bnportugal.gov.pt/viewer/271573/?offset=#page=46&viewer=picture&o=info&n=0&q= | N29: C:\Users\mbaptista\OneDrive - Biblioteca Nacional de Portugal\Documentos\python\camoniana\imagens\capas\ | O29: =CONCATENATE(N29,A29,"\",B29,"\",C29,".jpg") -> C:\Users\mbaptista\OneDrive - Biblioteca Nacional de Portugal\Documentos\python\camoniana\imagens\capas\381465\\46.jpg | P29: =HYPERLINK(O29) -> C:\Users\mbaptista\OneDrive - Biblioteca Nacional de Portugal\Documentos\python\camoniana\imagens\capas\381465\\46.jpg | T29: 5, 10, 11, 43, 46 , 47, 101, 160, 161, 163, 235, 237, 291, 293, 343, 345, 347, 397, 443, 445, 495 , 545, 547, 627, 644
A30: 381465 | C30: 47 | D30: https://purl.pt/43233 | E30: https://purl.pt/43233 | F30: 271573 | G30: https://permalinkbnd.bnportugal.gov.pt/viewer/ | H30: /?offset=#page= | I30: &viewer=picture&o=info&n=0&q= | J30: =CONCATENATE(G30,F30,H30,C30,I30) -> https://permalinkbnd.bnportugal.gov.pt/viewer/271573/?offset=#page=47&viewer=picture&o=info&n=0&q= | K30: 5 [site], 10 [site], 11 [site], 43, 46 [Vasco da Gama], 47, 100, 101, 160, 161, 163, 235, 237, 289, 291 [site Adamastor], 293, 343 [site apontamento livros e pena], 345, 347, 397, 443, 445, 495 [site Mercúrio, caduceu e navegador], 545 [site máquina do mundo], 547, 625, 627, 644 [monge com livro] [portadas, retrato de Camões, fotogravuras em cada Canto] | L30: =VLOOKUP(A30,Folha2!$A$2:$B$2019,2,FALSE) -> Os Lusíadas, 1898, obra dedicada à Comissão do Centenário e nos paratextos é referida a Celebração: Celebrações (1880); Paratextos argumentos e Iconografia figuras históricas. | M30: =HYPERLINK(J30) -> https://permalinkbnd.bnportugal.gov.pt/viewer/271573/?offset=#page=47&viewer=picture&o=info&n=0&q= | N30: C:\Users\mbaptista\OneDrive - Biblioteca Nacional de Portugal\Documentos\python\camoniana\imagens\capas\ | O30: =CONCATENATE(N30,A30,"\",B30,"\",C30,".jpg") -> C:\Users\mbaptista\OneDrive - Biblioteca Nacional de Portugal\Documentos\python\camoniana\imagens\capas\381465\\47.jpg | P30: =HYPERLINK(O30) -> C:\Users\mbaptista\OneDrive - Biblioteca Nacional de Portugal\Documentos\python\camoniana\imagens\capas\381465\\47.jpg | T30: 5, 10, 11, 43, 46 , 47, 101, 160, 161, 163, 235, 237, 291, 293, 343, 345, 347, 397, 443, 445, 495 , 545, 547, 627, 644
A31: 381465 | C31: 100 | D31: https://purl.pt/43233 | E31: https://purl.pt/43233 | F31: 271573 | G31: https://permalinkbnd.bnportugal.gov.pt/viewer/ | H31: /?offset=#page= | I31: &viewer=picture&o=info&n=0&q= | J31: =CONCATENATE(G31,F31,H31,C31,I31) -> https://permalinkbnd.bnportugal.gov.pt/viewer/271573/?offset=#page=100&viewer=picture&o=info&n=0&q= | K31: 5 [site], 10 [site], 11 [site], 43, 46 [Vasco da Gama], 47, 100, 101, 160, 161, 163, 235, 237, 289, 291 [site Adamastor], 293, 343 [site apontamento livros e pena], 345, 347, 397, 443, 445, 495 [site Mercúrio, caduceu e navegador], 545 [site máquina do mundo], 547, 625, 627, 644 [monge com livro] [portadas, retrato de Camões, fotogravuras em cada Canto] | L31: =VLOOKUP(A31,Folha2!$A$2:$B$2019,2,FALSE) -> Os Lusíadas, 1898, obra dedicada à Comissão do Centenário e nos paratextos é referida a Celebração: Celebrações (1880); Paratextos argumentos e Iconografia figuras históricas. | M31: =HYPERLINK(J31) -> https://permalinkbnd.bnportugal.gov.pt/viewer/271573/?offset=#page=100&viewer=picture&o=info&n=0&q= | N31: C:\Users\mbaptista\OneDrive - Biblioteca Nacional de Portugal\Documentos\python\camoniana\imagens\capas\ | O31: =CONCATENATE(N31,A31,"\",B31,"\",C31,".jpg") -> C:\Users\mbaptista\OneDrive - Biblioteca Nacional de Portugal\Documentos\python\camoniana\imagens\capas\381465\\100.jpg | P31: =HYPERLINK(O31) -> C:\Users\mbaptista\OneDrive - Biblioteca Nacional de Portugal\Documentos\python\camoniana\imagens\capas\381465\\100.jpg | T31: 5, 10, 11, 43, 46 , 47, 101, 160, 161, 163, 235, 237, 291, 293, 343, 345, 347, 397, 443, 445, 495 , 545, 547, 627, 644
A32: 381465 | C32: 101 | D32: https://purl.pt/43233 | E32: https://purl.pt/43233 | F32: 271573 | G32: https://permalinkbnd.bnportugal.gov.pt/viewer/ | H32: /?offset=#page= | I32: &viewer=picture&o=info&n=0&q= | J32: =CONCATENATE(G32,F32,H32,C32,I32) -> https://permalinkbnd.bnportugal.gov.pt/viewer/271573/?offset=#page=101&viewer=picture&o=info&n=0&q= | K32: 5 [site], 10 [site], 11 [site], 43, 46 [Vasco da Gama], 47, 100, 101, 160, 161, 163, 235, 237, 289, 291 [site Adamastor], 293, 343 [site apontamento livros e pena], 345, 347, 397, 443, 445, 495 [site Mercúrio, caduceu e navegador], 545 [site máquina do mundo], 547, 625, 627, 644 [monge com livro] [portadas, retrato de Camões, fotogravuras em cada Canto] | L32: =VLOOKUP(A32,Folha2!$A$2:$B$2019,2,FALSE) -> Os Lusíadas, 1898, obra dedicada à Comissão do Centenário e nos paratextos é referida a Celebração: Celebrações (1880); Paratextos argumentos e Iconografia figuras históricas. | M32: =HYPERLINK(J32) -> https://permalinkbnd.bnportugal.gov.pt/viewer/271573/?offset=#page=101&viewer=picture&o=info&n=0&q= | N32: C:\Users\mbaptista\OneDrive - Biblioteca Nacional de Portugal\Documentos\python\camoniana\imagens\capas\ | O32: =CONCATENATE(N32,A32,"\",B32,"\",C32,".jpg") -> C:\Users\mbaptista\OneDrive - Biblioteca Nacional de Portugal\Documentos\python\camoniana\imagens\capas\381465\\101.jpg | P32: =HYPERLINK(O32) -> C:\Users\mbaptista\OneDrive - Biblioteca Nacional de Portugal\Documentos\python\camoniana\imagens\capas\381465\\101.jpg | T32: 5, 10, 11, 43, 46 , 47, 101, 160, 161, 163, 235, 237, 291, 293, 343, 345, 347, 397, 443, 445, 495 , 545, 547, 627, 644
A33: 381465 | C33: 160 | D33: https://purl.pt/43233 | E33: https://purl.pt/43233 | F33: 271573 | G33: https://permalinkbnd.bnportugal.gov.pt/viewer/ | H33: /?offset=#page= | I33: &viewer=picture&o=info&n=0&q= | J33: =CONCATENATE(G33,F33,H33,C33,I33) -> https://permalinkbnd.bnportugal.gov.pt/viewer/271573/?offset=#page=160&viewer=picture&o=info&n=0&q= | K33: 5 [site], 10 [site], 11 [site], 43, 46 [Vasco da Gama], 47, 100, 101, 160, 161, 163, 235, 237, 289, 291 [site Adamastor], 293, 343 [site apontamento livros e pena], 345, 347, 397, 443, 445, 495 [site Mercúrio, caduceu e navegador], 545 [site máquina do mundo], 547, 625, 627, 644 [monge com livro] [portadas, retrato de Camões, fotogravuras em cada Canto] | L33: =VLOOKUP(A33,Folha2!$A$2:$B$2019,2,FALSE) -> Os Lusíadas, 1898, obra dedicada à Comissão do Centenário e nos paratextos é referida a Celebração: Celebrações (1880); Paratextos argumentos e Iconografia figuras históricas. | M33: =HYPERLINK(J33) -> https://permalinkbnd.bnportugal.gov.pt/viewer/271573/?offset=#page=160&viewer=picture&o=info&n=0&q= | N33: C:\Users\mbaptista\OneDrive - Biblioteca Nacional de Portugal\Documentos\python\camoniana\imagens\capas\ | O33: =CONCATENATE(N33,A33,"\",B33,"\",C33,".jpg") -> C:\Users\mbaptista\OneDrive - Biblioteca Nacional de Portugal\Documentos\python\camoniana\imagens\capas\381465\\160.jpg | P33: =HYPERLINK(O33) -> C:\Users\mbaptista\OneDrive - Biblioteca Nacional de Portugal\Documentos\python\camoniana\imagens\capas\381465\\160.jpg | T33: 5, 10, 11, 43, 46 , 47, 101, 160, 161, 163, 235, 237, 291, 293, 343, 345, 347, 397, 443, 445, 495 , 545, 547, 627, 644
A34: 381465 | C34: 161 | D34: https://purl.pt/43233 | E34: https://purl.pt/43233 | F34: 271573 | G34: https://permalinkbnd.bnportugal.gov.pt/viewer/ | H34: /?offset=#page= | I34: &viewer=picture&o=info&n=0&q= | J34: =CONCATENATE(G34,F34,H34,C34,I34) -> https://permalinkbnd.bnportugal.gov.pt/viewer/271573/?offset=#page=161&viewer=picture&o=info&n=0&q= | K34: 5 [site], 10 [site], 11 [site], 43, 46 [Vasco da Gama], 47, 100, 101, 160, 161, 163, 235, 237, 289, 291 [site Adamastor], 293, 343 [site apontamento livros e pena], 345, 347, 397, 443, 445, 495 [site Mercúrio, caduceu e navegador], 545 [site máquina do mundo], 547, 625, 627, 644 [monge com livro] [portadas, retrato de Camões, fotogravuras em cada Canto] | L34: =VLOOKUP(A34,Folha2!$A$2:$B$2019,2,FALSE) -> Os Lusíadas, 1898, obra dedicada à Comissão do Centenário e nos paratextos é referida a Celebração: Celebrações (1880); Paratextos argumentos e Iconografia figuras históricas. | M34: =HYPERLINK(J34) -> https://permalinkbnd.bnportugal.gov.pt/viewer/271573/?offset=#page=161&viewer=picture&o=info&n=0&q= | N34: C:\Users\mbaptista\OneDrive - Biblioteca Nacional de Portugal\Documentos\python\camoniana\imagens\capas\ | O34: =CONCATENATE(N34,A34,"\",B34,"\",C34,".jpg") -> C:\Users\mbaptista\OneDrive - Biblioteca Nacional de Portugal\Documentos\python\camoniana\imagens\capas\381465\\161.jpg | P34: =HYPERLINK(O34) -> C:\Users\mbaptista\OneDrive - Biblioteca Nacional de Portugal\Documentos\python\camoniana\imagens\capas\381465\\161.jpg | T34: 5, 10, 11, 43, 46 , 47, 101, 160, 161, 163, 235, 237, 291, 293, 343, 345, 347, 397, 443, 445, 495 , 545, 547, 627, 644
A35: 381465 | C35: 163 | D35: https://purl.pt/43233 | E35: https://purl.pt/43233 | F35: 271573 | G35: https://permalinkbnd.bnportugal.gov.pt/viewer/ | H35: /?offset=#page= | I35: &viewer=picture&o=info&n=0&q= | J35: =CONCATENATE(G35,F35,H35,C35,I35) -> https://permalinkbnd.bnportugal.gov.pt/viewer/271573/?offset=#page=163&viewer=picture&o=info&n=0&q= | K35: 5 [site], 10 [site], 11 [site], 43, 46 [Vasco da Gama], 47, 100, 101, 160, 161, 163, 235, 237, 289, 291 [site Adamastor], 293, 343 [site apontamento livros e pena], 345, 347, 397, 443, 445, 495 [site Mercúrio, caduceu e navegador], 545 [site máquina do mundo], 547, 625, 627, 644 [monge com livro] [portadas, retrato de Camões, fotogravuras em cada Canto] | L35: =VLOOKUP(A35,Folha2!$A$2:$B$2019,2,FALSE) -> Os Lusíadas, 1898, obra dedicada à Comissão do Centenário e nos paratextos é referida a Celebração: Celebrações (1880); Paratextos argumentos e Iconografia figuras históricas. | M35: =HYPERLINK(J35) -> https://permalinkbnd.bnportugal.gov.pt/viewer/271573/?offset=#page=163&viewer=picture&o=info&n=0&q= | N35: C:\Users\mbaptista\OneDrive - Biblioteca Nacional de Portugal\Documentos\python\camoniana\imagens\capas\ | O35: =CONCATENATE(N35,A35,"\",B35,"\",C35,".jpg") -> C:\Users\mbaptista\OneDrive - Biblioteca Nacional de Portugal\Documentos\python\camoniana\imagens\capas\381465\\163.jpg | P35: =HYPERLINK(O35) -> C:\Users\mbaptista\OneDrive - Biblioteca Nacional de Portugal\Documentos\python\camoniana\imagens\capas\381465\\163.jpg | T35: 5, 10, 11, 43, 46 , 47, 101, 160, 161, 163, 235, 237, 291, 293, 343, 345, 347, 397, 443, 445, 495 , 545, 547, 627, 644
A36: 381465 | C36: 235 | D36: https://purl.pt/43233 | E36: https://purl.pt/43233 | F36: 271573 | G36: https://permalinkbnd.bnportugal.gov.pt/viewer/ | H36: /?offset=#page= | I36: &viewer=picture&o=info&n=0&q= | J36: =CONCATENATE(G36,F36,H36,C36,I36) -> https://permalinkbnd.bnportugal.gov.pt/viewer/271573/?offset=#page=235&viewer=picture&o=info&n=0&q= | K36: 5 [site], 10 [site], 11 [site], 43, 46 [Vasco da Gama], 47, 100, 101, 160, 161, 163, 235, 237, 289, 291 [site Adamastor], 293, 343 [site apontamento livros e pena], 345, 347, 397, 443, 445, 495 [site Mercúrio, caduceu e navegador], 545 [site máquina do mundo], 547, 625, 627, 644 [monge com livro] [portadas, retrato de Camões, fotogravuras em cada Canto] | L36: =VLOOKUP(A36,Folha2!$A$2:$B$2019,2,FALSE) -> Os Lusíadas, 1898, obra dedicada à Comissão do Centenário e nos paratextos é referida a Celebração: Celebrações (1880); Paratextos argumentos e Iconografia figuras históricas. | M36: =HYPERLINK(J36) -> https://permalinkbnd.bnportugal.gov.pt/viewer/271573/?offset=#page=235&viewer=picture&o=info&n=0&q= | N36: C:\Users\mbaptista\OneDrive - Biblioteca Nacional de Portugal\Documentos\python\camoniana\imagens\capas\ | O36: =CONCATENATE(N36,A36,"\",B36,"\",C36,".jpg") -> C:\Users\mbaptista\OneDrive - Biblioteca Nacional de Portugal\Documentos\python\camoniana\imagens\capas\381465\\235.jpg | P36: =HYPERLINK(O36) -> C:\Users\mbaptista\OneDrive - Biblioteca Nacional de Portugal\Documentos\python\camoniana\imagens\capas\381465\\235.jpg | T36: 5, 10, 11, 43, 46 , 47, 101, 160, 161, 163, 235, 237, 291, 293, 343, 345, 347, 397, 443, 445, 495 , 545, 547, 627, 644
A37: 381465 | C37: 237 | D37: https://purl.pt/43233 | E37: https://purl.pt/43233 | F37: 271573 | G37: https://permalinkbnd.bnportugal.gov.pt/viewer/ | H37: /?offset=#page= | I37: &viewer=picture&o=info&n=0&q= | J37: =CONCATENATE(G37,F37,H37,C37,I37) -> https://permalinkbnd.bnportugal.gov.pt/viewer/271573/?offset=#page=237&viewer=picture&o=info&n=0&q= | K37: 5 [site], 10 [site], 11 [site], 43, 46 [Vasco da Gama], 47, 100, 101, 160, 161, 163, 235, 237, 289, 291 [site Adamastor], 293, 343 [site apontamento livros e pena], 345, 347, 397, 443, 445, 495 [site Mercúrio, caduceu e navegador], 545 [site máquina do mundo], 547, 625, 627, 644 [monge com livro] [portadas, retrato de Camões, fotogravuras em cada Canto] | L37: =VLOOKUP(A37,Folha2!$A$2:$B$2019,2,FALSE) -> Os Lusíadas, 1898, obra dedicada à Comissão do Centenário e nos paratextos é referida a Celebração: Celebrações (1880); Paratextos argumentos e Iconografia figuras históricas. | M37: =HYPERLINK(J37) -> https://permalinkbnd.bnportugal.gov.pt/viewer/271573/?offset=#page=237&viewer=picture&o=info&n=0&q= | N37: C:\Users\mbaptista\OneDrive - Biblioteca Nacional de Portugal\Documentos\python\camoniana\imagens\capas\ | O37: =CONCATENATE(N37,A37,"\",B37,"\",C37,".jpg") -> C:\Users\mbaptista\OneDrive - Biblioteca Nacional de Portugal\Documentos\python\camoniana\imagens\capas\381465\\237.jpg | P37: =HYPERLINK(O37) -> C:\Users\mbaptista\OneDrive - Biblioteca Nacional de Portugal\Documentos\python\camoniana\imagens\capas\381465\\237.jpg | T37: 5, 10, 11, 43, 46 , 47, 101, 160, 161, 163, 235, 237, 291, 293, 343, 345, 347, 397, 443, 445, 495 , 545, 547, 627, 644
... A51: 381465 | C51: 627 | D51: https://purl.pt/43233 | E51: https://purl.pt/43233 | F51: 271573 | G51: https://permalinkbnd.bnportugal.gov.pt/viewer/ | H51: /?offset=#page= | I51: &viewer=picture&o=info&n=0&q= | J51: =CONCATENATE(G51,F51,H51,C51,I51) -> https://permalinkbnd.bnportugal.gov.pt/viewer/271573/?offset=#page=627&viewer=picture&o=info&n=0&q= | K51: 5 [site], 10 [site], 11 [site], 43, 46 [Vasco da Gama], 47, 100, 101, 160, 161, 163, 235, 237, 289, 291 [site Adamastor], 293, 343 [site apontamento livros e pena], 345, 347, 397, 443, 445, 495 [site Mercúrio, caduceu e navegador], 545 [site máquina do mundo], 547, 625, 627, 644 [monge com livro] [portadas, retrato de Camões, fotogravuras em cada Canto] | L51: =VLOOKUP(A51,Folha2!$A$2:$B$2019,2,FALSE) -> Os Lusíadas, 1898, obra dedicada à Comissão do Centenário e nos paratextos é referida a Celebração: Celebrações (1880); Paratextos argumentos e Iconografia figuras históricas. | M51: =HYPERLINK(J51) -> https://permalinkbnd.bnportugal.gov.pt/viewer/271573/?offset=#page=627&viewer=picture&o=info&n=0&q= | N51: C:\Users\mbaptista\OneDrive - Biblioteca Nacional de Portugal\Documentos\python\camoniana\imagens\capas\ | O51: =CONCATENATE(N51,A51,"\",B51,"\",C51,".jpg") -> C:\Users\mbaptista\OneDrive - Biblioteca Nacional de Portugal\Documentos\python\camoniana\imagens\capas\381465\\627.jpg | P51: =HYPERLINK(O51) -> C:\Users\mbaptista\OneDrive - Biblioteca Nacional de Portugal\Documentos\python\camoniana\imagens\capas\381465\\627.jpg | T51: 5, 10, 11, 43, 46 , 47, 101, 160, 161, 163, 235, 237, 291, 293, 343, 345, 347, 397, 443, 445, 495 , 545, 547, 627, 644
A52: 381465 | B52: 1 | C52: 644 | D52: https://purl.pt/43233 | E52: https://purl.pt/43233 | F52: 271573 | G52: https://permalinkbnd.bnportugal.gov.pt/viewer/ | H52: /?offset=#page= | I52: &viewer=picture&o=info&n=0&q= | J52: =CONCATENATE(G52,F52,H52,C52,I52) -> https://permalinkbnd.bnportugal.gov.pt/viewer/271573/?offset=#page=644&viewer=picture&o=info&n=0&q= | K52: 5 [site], 10 [site], 11 [site], 43, 46 [Vasco da Gama], 47, 100, 101, 160, 161, 163, 235, 237, 289, 291 [site Adamastor], 293, 343 [site apontamento livros e pena], 345, 347, 397, 443, 445, 495 [site Mercúrio, caduceu e navegador], 545 [site máquina do mundo], 547, 625, 627, 644 [monge com livro] [portadas, retrato de Camões, fotogravuras em cada Canto] | L52: =VLOOKUP(A52,Folha2!$A$2:$B$2019,2,FALSE) -> Os Lusíadas, 1898, obra dedicada à Comissão do Centenário e nos paratextos é referida a Celebração: Celebrações (1880); Paratextos argumentos e Iconografia figuras históricas. | M52: =HYPERLINK(J52) -> https://permalinkbnd.bnportugal.gov.pt/viewer/271573/?offset=#page=644&viewer=picture&o=info&n=0&q= | N52: C:\Users\mbaptista\OneDrive - Biblioteca Nacional de Portugal\Documentos\python\camoniana\imagens\capas\ | O52: =CONCATENATE(N52,A52,"\",B52,"\",C52,".jpg") -> C:\Users\mbaptista\OneDrive - Biblioteca Nacional de Portugal\Documentos\python\camoniana\imagens\capas\381465\1\644.jpg | P52: =HYPERLINK(O52) -> C:\Users\mbaptista\OneDrive - Biblioteca Nacional de Portugal\Documentos\python\camoniana\imagens\capas\381465\1\644.jpg | R52: https://permalinkbnd.bnportugal.gov.pt/viewer/271573/?offset=#page=644&viewer=picture&o=info&n=0&q= | T52: 5, 10, 11, 43, 46 , 47, 101, 160, 161, 163, 235, 237, 291, 293, 343, 345, 347, 397, 443, 445, 495 , 545, 547, 627, 644 | W52: Sim
A53: 381468 | B53: 1 | C53: 8 | D53: https://purl.pt/43745 | E53: https://purl.pt/43745 | F53: 274087 | G53: https://permalinkbnd.bnportugal.gov.pt/viewer/ | H53: /?offset=#page= | I53: &viewer=picture&o=info&n=0&q= | J53: =CONCATENATE(G53,F53,H53,C53,I53) -> https://permalinkbnd.bnportugal.gov.pt/viewer/274087/?offset=#page=8&viewer=picture&o=info&n=0&q= | K53: 8 [site retrato de Camões] | L53: =VLOOKUP(A53,Folha2!$A$2:$B$2019,2,FALSE) -> Os Lusíadas/Los Portugueses, D. Carlos Soler y Arques, 1873. Bilingue, sem argumentos. Trad. Paratextos; Trad. Paratextos vida; Trad. Paratextos notas. | M53: =HYPERLINK(J53) -> https://permalinkbnd.bnportugal.gov.pt/viewer/274087/?offset=#page=8&viewer=picture&o=info&n=0&q= | N53: C:\Users\mbaptista\OneDrive - Biblioteca Nacional de Portugal\Documentos\python\camoniana\imagens\capas\ | O53: =CONCATENATE(N53,A53,"\",B53,"\",C53,".jpg") -> C:\Users\mbaptista\OneDrive - Biblioteca Nacional de Portugal\Documentos\python\camoniana\imagens\capas\381468\1\8.jpg | P53: =HYPERLINK(O53) -> C:\Users\mbaptista\OneDrive - Biblioteca Nacional de Portugal\Documentos\python\camoniana\imagens\capas\381468\1\8.jpg | R53: https://permalinkbnd.bnportugal.gov.pt/viewer/274087/?offset=#page=8&viewer=picture&o=info&n=0&q= | T53: 8 | W53: Sim
A54: 381701 | B54: 1 | C54: 11 | D54: https://purl.pt/43724 | E54: https://purl.pt/43724 | F54: 281141 | G54: https://permalinkbnd.bnportugal.gov.pt/viewer/ | H54: /?offset=#page= | I54: &viewer=picture&o=info&n=0&q= | J54: =CONCATENATE(G54,F54,H54,C54,I54) -> https://permalinkbnd.bnportugal.gov.pt/viewer/281141/?offset=#page=11&viewer=picture&o=info&n=0&q= | K54: 11 | L54: =VLOOKUP(A54,Folha2!$A$2:$B$2019,2,FALSE) -> Inês de Castro, 1873. [cópia digital não abre, consultado PDF via Miguel] Edição em catorze línguas, um ano depois das Celebrações (1872), mas sem referência. | M54: =HYPERLINK(J54) -> https://permalinkbnd.bnportugal.gov.pt/viewer/281141/?offset=#page=11&viewer=picture&o=info&n=0&q= | N54: C:\Users\mbaptista\OneDrive - Biblioteca Nacional de Portugal\Documentos\python\camoniana\imagens\capas\ | O54: =CONCATENATE(N54,A54,"\",B54,"\",C54,".jpg") -> C:\Users\mbaptista\OneDrive - Biblioteca Nacional de Portugal\Documentos\python\camoniana\imagens\capas\381701\1\11.jpg | P54: =HYPERLINK(O54) -> C:\Users\mbaptista\OneDrive - Biblioteca Nacional de Portugal\Documentos\python\camoniana\imagens\capas\381701\1\11.jpg | R54: https://permalinkbnd.bnportugal.gov.pt/viewer/281141/?offset=#page=11&viewer=picture&o=info&n=0&q= | T54: 11 | W54: Sim
A55: 381889 | B55: 1 | C55: 1 | D55: https://purl.pt/43659 | E55: https://purl.pt/43659 | F55: 273118 | G55: https://permalinkbnd.bnportugal.gov.pt/viewer/ | H55: /?offset=#page= | I55: &viewer=picture&o=info&n=0&q= | J55: =CONCATENATE(G55,F55,H55,C55,I55) -> https://permalinkbnd.bnportugal.gov.pt/viewer/273118/?offset=#page=1&viewer=picture&o=info&n=0&q= | K55: 1 [Inês de Castro, Vasco da Gama, Catarina de Ataíde e retrato de Camões] | L55: =VLOOKUP(A55,Folha2!$A$2:$B$2019,2,FALSE) -> Pérolas de Camões. 1880. Inês de Castro, Adamastor, Ilha dos Amores, sem argumentos, Soneto a Natércia [em Antologia não existe fragmento/soneto lírica?]. Iconografia, figuras históricas. | M55: =HYPERLINK(J55) -> https://permalinkbnd.bnportugal.gov.pt/viewer/273118/?offset=#page=1&viewer=picture&o=info&n=0&q= | N55: C:\Users\mbaptista\OneDrive - Biblioteca Nacional de Portugal\Documentos\python\camoniana\imagens\capas\ | O55: =CONCATENATE(N55,A55,"\",B55,"\",C55,".jpg") -> C:\Users\mbaptista\OneDrive - Biblioteca Nacional de Portugal\Documentos\python\camoniana\imagens\capas\381889\1\1.jpg | P55: =HYPERLINK(O55) -> C:\Users\mbaptista\OneDrive - Biblioteca Nacional de Portugal\Documentos\python\camoniana\imagens\capas\381889\1\1.jpg | R55: https://permalinkbnd.bnportugal.gov.pt/viewer/273118/?offset=#page=1&viewer=picture&o=info&n=0&q= | T55: 1 | W55: Sim
A56: 381903 | B56: 1 | C56: 5 | D56: https://purl.pt/42920 | E56: https://purl.pt/42920 | F56: 270037 | G56: https://permalinkbnd.bnportugal.gov.pt/viewer/ | H56: /?offset=#page= | I56: &viewer=picture&o=info&n=0&q= | J56: =CONCATENATE(G56,F56,H56,C56,I56) -> https://permalinkbnd.bnportugal.gov.pt/viewer/270037/?offset=#page=5&viewer=picture&o=info&n=0&q= | K56: 5 [1.º] | L56: =VLOOKUP(A56,Folha2!$A$2:$B$2019,2,FALSE) -> Artigo polaco? Séc. XIX: " Luiz de Camoens" da autoria de K. Kaszewskiego 1880, continuação do texto no CAM. 45//3 A. | M56: =HYPERLINK(J56) -> https://permalinkbnd.bnportugal.gov.pt/viewer/270037/?offset=#page=5&viewer=picture&o=info&n=0&q= | N56: C:\Users\mbaptista\OneDrive - Biblioteca Nacional de Portugal\Documentos\python\camoniana\imagens\capas\ | O56: =CONCATENATE(N56,A56,"\",B56,"\",C56,".jpg") -> C:\Users\mbaptista\OneDrive - Biblioteca Nacional de Portugal\Documentos\python\camoniana\imagens\capas\381903\1\5.jpg | P56: =HYPERLINK(O56) -> C:\Users\mbaptista\OneDrive - Biblioteca Nacional de Portugal\Documentos\python\camoniana\imagens\capas\381903\1\5.jpg | R56: https://permalinkbnd.bnportugal.gov.pt/viewer/270037/?offset=#page=5&viewer=picture&o=info&n=0&q= | T56: 5 | W56: Sim
A57: 382749 | B57: 1 | C57: 7 | D57: https://purl.pt/42835 | E57: https://purl.pt/42835 | F57: 270109 | G57: https://permalinkbnd.bnportugal.gov.pt/viewer/ | H57: /?offset=#page= | I57: &viewer=picture&o=info&n=0&q= | J57: =CONCATENATE(G57,F57,H57,C57,I57) -> https://permalinkbnd.bnportugal.gov.pt/viewer/270109/?offset=#page=7&viewer=picture&o=info&n=0&q= | K57: 7 [site], 19, 23 [frisos site, esta obra contém mais apontamentos e frisos belíssimos] | L57: =VLOOKUP(A57,Folha2!$A$2:$B$2019,2,FALSE) -> Pretidão de amor. Texto+tradução, 1893-1895. 2 Vols [dois exemplares da mesma obra: n.º 56 de Tomás de Carvalho e 137 da BNL]. Trad. Paratextos e Mulheres [Alice Moderno trad. para francês; Josephine Lévi trad. para italiano; Josephine de Zaleska trad. polaco; Josephine Constantini-Arntzen trad. norueguês; Mathilde Perry Conorado trad. para castelhano]. Celebrações (1880), traduções em celebração do 313.º aniversário do passamento de Camões (1893) | M57: =HYPERLINK(J57) -> https://permalinkbnd.bnportugal.gov.pt/viewer/270109/?offset=#page=7&viewer=picture&o=info&n=0&q= | N57: C:\Users\mbaptista\OneDrive - Biblioteca Nacional de Portugal\Documentos\python\camoniana\imagens\capas\ | O57: =CONCATENATE(N57,A57,"\",B57,"\",C57,".jpg") -> C:\Users\mbaptista\OneDrive - Biblioteca Nacional de Portugal\Documentos\python\camoniana\imagens\capas\382749\1\7.jpg | P57: =HYPERLINK(O57) -> C:\Users\mbaptista\OneDrive - Biblioteca Nacional de Portugal\Documentos\python\camoniana\imagens\capas\382749\1\7.jpg | R57: https://permalinkbnd.bnportugal.gov.pt/viewer/270109/?offset=#page=7&viewer=picture&o=info&n=0&q= | W57: Sim
A58: 382749 | B58: 1 | C58: 19 | D58: https://purl.pt/42835 | E58: https://purl.pt/42835 | F58: 270109 | G58: https://permalinkbnd.bnportugal.gov.pt/viewer/ | H58: /?offset=#page= | I58: &viewer=picture&o=info&n=0&q= | J58: =CONCATENATE(G58,F58,H58,C58,I58) -> https://permalinkbnd.bnportugal.gov.pt/viewer/270109/?offset=#page=19&viewer=picture&o=info&n=0&q= | L58: =VLOOKUP(A58,Folha2!$A$2:$B$2019,2,FALSE) -> Pretidão de amor. Texto+tradução, 1893-1895. 2 Vols [dois exemplares da mesma obra: n.º 56 de Tomás de Carvalho e 137 da BNL]. Trad. Paratextos e Mulheres [Alice Moderno trad. para francês; Josephine Lévi trad. para italiano; Josephine de Zaleska trad. polaco; Josephine Constantini-Arntzen trad. norueguês; Mathilde Perry Conorado trad. para castelhano]. Celebrações (1880), traduções em celebração do 313.º aniversário do passamento de Camões (1893) | M58: =HYPERLINK(J58) -> https://permalinkbnd.bnportugal.gov.pt/viewer/270109/?offset=#page=19&viewer=picture&o=info&n=0&q= | N58: C:\Users\mbaptista\OneDrive - Biblioteca Nacional de Portugal\Documentos\python\camoniana\imagens\capas\ | O58: =CONCATENATE(N58,A58,"\",B58,"\",C58,".jpg") -> C:\Users\mbaptista\OneDrive - Biblioteca Nacional de Portugal\Documentos\python\camoniana\imagens\capas\382749\1\19.jpg | P58: =HYPERLINK(O58) -> C:\Users\mbaptista\OneDrive - Biblioteca Nacional de Portugal\Documentos\python\camoniana\imagens\capas\382749\1\19.jpg | R58: https://permalinkbnd.bnportugal.gov.pt/viewer/270109/?offset=#page=19&viewer=picture&o=info&n=0&q= | W58: Sim
A59: 382749 | B59: 1 | C59: 23 | D59: https://purl.pt/42835 | E59: https://purl.pt/42835 | F59: 270109 | G59: https://permalinkbnd.bnportugal.gov.pt/viewer/ | H59: /?offset=#page= | I59: &viewer=picture&o=info&n=0&q= | J59: =CONCATENATE(G59,F59,H59,C59,I59) -> https://permalinkbnd.bnportugal.gov.pt/viewer/270109/?offset=#page=23&viewer=picture&o=info&n=0&q= | L59: =VLOOKUP(A59,Folha2!$A$2:$B$2019,2,FALSE) -> Pretidão de amor. Texto+tradução, 1893-1895. 2 Vols [dois exemplares da mesma obra: n.º 56 de Tomás de Carvalho e 137 da BNL]. Trad. Paratextos e Mulheres [Alice Moderno trad. para francês; Josephine Lévi trad. para italiano; Josephine de Zaleska trad. polaco; Josephine Constantini-Arntzen trad. norueguês; Mathilde Perry Conorado trad. para castelhano]. Celebrações (1880), traduções em celebração do 313.º aniversário do passamento de Camões (1893) | M59: =HYPERLINK(J59) -> https://permalinkbnd.bnportugal.gov.pt/viewer/270109/?offset=#page=23&viewer=picture&o=info&n=0&q= | N59: C:\Users\mbaptista\OneDrive - Biblioteca Nacional de Portugal\Documentos\python\camoniana\imagens\capas\ | O59: =CONCATENATE(N59,A59,"\",B59,"\",C59,".jpg") -> C:\Users\mbaptista\OneDrive - Biblioteca Nacional de Portugal\Documentos\python\camoniana\imagens\capas\382749\1\23.jpg | P59: =HYPERLINK(O59) -> C:\Users\mbaptista\OneDrive - Biblioteca Nacional de Portugal\Documentos\python\camoniana\imagens\capas\382749\1\23.jpg | R59: https://permalinkbnd.bnportugal.gov.pt/viewer/270109/?offset=#page=23&viewer=picture&o=info&n=0&q= | W59: Sim
A60: 382834 | B60: 1 | C60: 11 | D60: https://purl.pt/43815 | E60: https://purl.pt/43815 | F60: 273316 | G60: https://permalinkbnd.bnportugal.gov.pt/viewer/ | H60: /?offset=#page= | I60: &viewer=picture&o=info&n=0&q= | J60: =CONCATENATE(G60,F60,H60,C60,I60) -> https://permalinkbnd.bnportugal.gov.pt/viewer/273316/?offset=#page=11&viewer=picture&o=info&n=0&q= | K60: 11 [caravela com Vasco da Gama] | L60: =VLOOKUP(A60,Folha2!$A$2:$B$2019,2,FALSE) -> Benoliel, Sobre o episódio do Adamastor, 1898. Bibliografia crítica, estudo. | M60: =HYPERLINK(J60) -> https://permalinkbnd.bnportugal.gov.pt/viewer/273316/?offset=#page=11&viewer=picture&o=info&n=0&q= | N60: C:\Users\mbaptista\OneDrive - Biblioteca Nacional de Portugal\Documentos\python\camoniana\imagens\capas\ | O60: =CONCATENATE(N60,A60,"\",B60,"\",C60,".jpg") -> C:\Users\mbaptista\OneDrive - Biblioteca Nacional de Portugal\Documentos\python\camoniana\imagens\capas\382834\1\11.jpg | P60: =HYPERLINK(O60) -> C:\Users\mbaptista\OneDrive - Biblioteca Nacional de Portugal\Documentos\python\camoniana\imagens\capas\382834\1\11.jpg | R60: https://permalinkbnd.bnportugal.gov.pt/viewer/273316/?offset=#page=11&viewer=picture&o=info&n=0&q= | T60: 11 | W60: Sim
A61: 382844 | B61: 1 | C61: 3 | D61: https://purl.pt/43227 | E61: https://purl.pt/43227 | F61: 271559 | G61: https://permalinkbnd.bnportugal.gov.pt/viewer/ | H61: /?offset=#page= | I61: &viewer=picture&o=info&n=0&q= | J61: =CONCATENATE(G61,F61,H61,C61,I61) -> https://permalinkbnd.bnportugal.gov.pt/viewer/271559/?offset=#page=3&viewer=picture&o=info&n=0&q= | K61: 3 | L61: =VLOOKUP(A61,Folha2!$A$2:$B$2019,2,FALSE) -> Poema a Camões*Vida+Notas1880 [notas sobre a vida do Poeta, Im. 13]. Celebrações (1880), recepção criativa, tematização. Inclui soneto de Camões. | M61: =HYPERLINK(J61) -> https://permalinkbnd.bnportugal.gov.pt/viewer/271559/?offset=#page=3&viewer=picture&o=info&n=0&q= | N61: C:\Users\mbaptista\OneDrive - Biblioteca Nacional de Portugal\Documentos\python\camoniana\imagens\capas\ | O61: =CONCATENATE(N61,A61,"\",B61,"\",C61,".jpg") -> C:\Users\mbaptista\OneDrive - Biblioteca Nacional de Portugal\Documentos\python\camoniana\imagens\capas\382844\1\3.jpg | P61: =HYPERLINK(O61) -> C:\Users\mbaptista\OneDrive - Biblioteca Nacional de Portugal\Documentos\python\camoniana\imagens\capas\382844\1\3.jpg | R61: https://permalinkbnd.bnportugal.gov.pt/viewer/271559/?offset=#page=3&viewer=picture&o=info&n=0&q= | W61: Sim
...

Sheet Folha4
A1: pasta | B1: volume | C1: imagem | D1: purl-hiperligação | E1: purl 2 | F1: n bnd | G1: l1 | H1: l2 | I1: l3 | J1: l4 | K1: imagens_texto | L1: Notas | M1: link página | N1: l5 | O1: l6 | P1: link imagem | Q1: nada | R1: url_página | S1: nada 2 | T1: imagens | U1: notas Regina | V1: notas Regina 2 | W1: tem JPG
A2: 367428 | B2: 1 | C2: 1 | D2: https://purl.pt/43428 | E2: https://purl.pt/43428 | F2: 272369 | G2: https://permalinkbnd.bnportugal.gov.pt/viewer/ | H2: /?offset=#page= | I2: &viewer=picture&o=info&n=0&q= | J2: =CONCATENATE(G2,F2,H2,C2,I2) -> https://permalinkbnd.bnportugal.gov.pt/viewer/272369/?offset=#page=1&viewer=picture&o=info&n=0&q= | K2: 1 | L2: =VLOOKUP(A2,Folha2!$A$2:$B$2019,2,FALSE) -> I Lusiadi. Antonio Nervi, 1882. Trad. Paratextos vida. Trad. Paratextos notas (de rodapé em cada Canto). Trad. Paratextos argumentos. | M2: =HYPERLINK(J2) -> https://permalinkbnd.bnportugal.gov.pt/viewer/272369/?offset=#page=1&viewer=picture&o=info&n=0&q= | N2: C:\Users\mbaptista\OneDrive - Biblioteca Nacional de Portugal\Documentos\python\camoniana\imagens\capas\ | O2: =CONCATENATE(N2,A2,"\",B2,"\",C2,".jpg") -> C:\Users\mbaptista\OneDrive - Biblioteca Nacional de Portugal\Documentos\python\camoniana\imagens\capas\367428\1\1.jpg | P2: =HYPERLINK(O2) -> C:\Users\mbaptista\OneDrive - Biblioteca Nacional de Portugal\Documentos\python\camoniana\imagens\capas\367428\1\1.jpg | R2: https://permalinkbnd.bnportugal.gov.pt/viewer/272369/?offset=#page=1&viewer=picture&o=info&n=0&q= | T2: 1 | W2: Sim
